Workbook

Sheet Company list 1
A1: [Client] target/buyer name
A2: Exchange rate as on date | B2: X
A3: =COUNTA(A7:A1048576) -> 70
A6: Company Name | B6: HQ | C6: Initial email | D6: Status | E6: Type | F6: Rationale | G6: Revenue from source | H6: Rev (INR Cr) | I6: Headcount | J6: Website link | K6: Contact Name | L6: Designation | M6: Email Id | N6: Linkedin | O6: Relevant Investments | P6: Bucket | Q6: Previous contact
A7: Mandala Capital | B7: Mauritius | C7: 46160 | D7: Got response | E7: PE | F7: Food and agriculture focused | H7: =IFERROR((G7*1000000*$B$2)/10000000,0) -> 0 | J7: https://mandala-capital.com/ | K7: Aditya Mody | L7: Managing Director | M7: amody@mandala-capital.com | N7: https://www.linkedin.com/in/modyaditya/ | O7: Godavari Biorefineries | P7: Direct | Q7: No
A8: JM Financial | B8: Mumbai | C8: 46160 | D8: Got response | E8: PE | F8: Growth Fund III focus on agri allied businesses | H8: =IFERROR((G8*1000000*$B$2)/10000000,0) -> 0 | J8: https://jmfpe.com/JMFinancialIndiaFund | K8: Vinit Rai | L8: Managing Director | M8: vinit.rai@jmfl.com | N8: https://www.linkedin.com/in/raivinit/ | O8: Bighaat Agro | P8: Direct | Q8: Yes
A9: Catamaran Ventures | B9: Bangalore | C9: 46160 | D9: Got response | E9: FO | F9: Narayana Murthy family investment office | H9: =IFERROR((G9*1000000*$B$2)/10000000,0) -> 0 | J9: https://catamaran.in/ | K9: Sheetal Unadkat Bhat | L9: Head of PE | M9: sheetal@catamaran.in | N9: https://www.linkedin.com/in/sheetal-unadkat-bhat-26a49111/ | O9: Akshayakalpa | P9: Direct | Q9: No
A10: Convergent Finance | B10: Mumbai | C10: 46160 | D10: Got response | E10: PE | F10: Food and agriculture sector investments | H10: =IFERROR((G10*1000000*$B$2)/10000000,0) -> 0 | J10: https://convergentfinance.com/ | K10: Harsha Raghavan | L10: Managing Partner | M10: harsha@convergentfinance.com | N10: https://www.linkedin.com/in/harsha-raghavan-1218a11b5/ | O10: Hindustan Foods Limited | P10: Direct | Q10: Yes
A11: Sharrp Ventures | B11: Mumbai | C11: 46160 | D11: 46188 | E11: FO | F11: Harsh Mariwala family investment office | H11: =IFERROR((G11*1000000*$B$2)/10000000,0) -> 0 | J11: https://www.sharrpventures.com/ | K11: Divya Gupta | L11: Principal | M11: divya.gupta@sharrpventures.com | N11: https://www.linkedin.com/in/divya-gupta-5b2a5814/ | O11: Parsons Nutritionals | P11: Direct | Q11: No
A12: DS Group | B12: Noida | C12: 46160 | D12: 46188 | E12: FO | F12: Dharampal Satyapal family investment office | H12: =IFERROR((G12*1000000*$B$2)/10000000,0) -> 0 | J12: https://www.dsgroup.com/ | K12: Kunal Bhanot | L12: N/A | M12: kunal.bhanot@dsgroup.com | N12: https://www.linkedin.com/in/kunal-bhanot-5273b139/ | O12: Agri | P12: Secondary | Q12: No
A13: RP Sanjiv Goenka Family Office | B13: Kolkata | C13: 46160 | D13: Got response | E13: FO | F13: Sanjiv Goenka family investment office | H13: =IFERROR((G13*1000000*$B$2)/10000000,0) -> 0 | J13: https://www.rpsg.in/ | K13: Anshumaan Khetawat | L13: N/A | M13: anshumaan.khetawat@rpsg.in | N13: https://www.linkedin.com/in/akhetawat/ | O13: Harrisons Malyalam Limited | P13: Direct | Q13: No
A14: Negen Capital | B14: Mumbai | C14: 46160 | D14: 46188 | E14: PMS | F14: Negen Investment Trust - Category III Alternative Investment Fund | H14: =IFERROR((G14*1000000*$B$2)/10000000,0) -> 0 | J14: https://www.negencat3.com/ | K14: Jigar Shah | L14: Director | M14: jigar@negencapital.com | N14: https://www.linkedin.com/in/jigar-shah-88a44b10/ | O14: N/A | P14: Secondary | Q14: No
A15: Lighthouse Funds | B15: Mumbai | C15: 46160 | D15: 46188 | E15: PE | F15: $25-100m cheque size | H15: =IFERROR((G15*1000000*$B$2)/10000000,0) -> 0 | J15: https://www.lhfunds.com/ | K15: Vivek Kumar | L15: Principal | M15: vivek@lhfunds.com | N15: https://www.linkedin.com/in/vivek-kumar-8ab93717/ | O15: Parsons Nutritionals | P15: Direct | Q15: No
A16: Carpediem Capital | B16: Mumbai | C16: 46160 | D16: Got response | E16: PE | F16: Invests in consumer and B2B brands | H16: =IFERROR((G16*1000000*$B$2)/10000000,0) -> 0 | J16: https://carpediem-capital.com/ | K16: Tejas Gupte | L16: Vice President | M16: tejas@carpediem-capital.com | N16: https://www.linkedin.com/in/tejas-gupte-57278698/ | O16: Trufrost & Butler | P16: Direct | Q16: No
A17: Narotam Sekhsaria Family Office | B17: Mumbai | C17: 46160 | D17: Got response | E17: FO | F17: Narotam Sekhsaria family investment office | H17: =IFERROR((G17*1000000*$B$2)/10000000,0) -> 0 | J17: https://www.sekhsaria.com/index.html | K17: Pankil Shah | L17: Investment Professional | M17: pankil@sekhsaria.com | N17: https://www.linkedin.com/in/pankil-shah-21b5194/ | O17: Satyanarayan Sekhsaria Private Limited | P17: Direct | Q17: No
A18: Anicut Capital | B18: Chennai | C18: Priya Mam reach out | D18: Priya Mam reach out | E18: PE/PC | F18: Invests in B2B and consumer brands | H18: =IFERROR((G18*1000000*$B$2)/10000000,0) -> 0 | J18: https://www.anicutcapital.com/ | O18: Khetika | P18: Direct | Q18: Yes
A19: Lok Capital | B19: Mumbai | C19: 46160 | D19: 46188 | E19: PE | F19: Invests in food and agriculture | H19: =IFERROR((G19*1000000*$B$2)/10000000,0) -> 0 | J19: https://www.lokcapital.com/ | K19: Sayyam Jain | L19: Investment Associate | M19: sayyam@lokcapital.com | N19: https://www.linkedin.com/in/sayyamvjain/ | O19: Siddhi Vinayak Agri Processing Pvt Ltd | P19: Direct | Q19: No
A20: Peepul Capital Advisors | B20: Chennai | C20: Priya Mam reach out | D20: Priya Mam reach out | E20: PE | F20: Invests in the consumer sector | H20: =IFERROR((G20*1000000*$B$2)/10000000,0) -> 0 | J20: https://www.peepulcapital.com/ | O20: Innovative Foods Ltd. | P20: Direct | Q20: No
A21: SN Damani | B21: Chennai | C21: Priya Mam reach out | D21: Priya Mam reach out | E21: Strategic | F21: Invests in food producers | H21: =IFERROR((G21*1000000*$B$2)/10000000,0) -> 0 | J21: https://www.sndamani.com/ | O21: Eeki | P21: Direct | Q21: No
A22: MGA Ventures | B22: Mumbai | C22: 46163 | D22: Got response | E22: FO | F22: Ashra family investment office | J22: https://www.mgaventures.in/ | K22: Hardiki Shah | L22: Investment Analyst | M22: hardikishah@mgaventures.in | N22: https://www.linkedin.com/in/hardikis/ | O22: Kan Biosys | P22: Secondary | Q22: No
A23: Menterra | B23: Bangalore | C23: 46163 | D23: 46191 | E23: PE/VC | F23: Invests in early stage companies/agri sector | H23: =IFERROR((G23*1000000*$B$2)/10000000,0) -> 0 | J23: https://www.menterra.com/ | K23: Mukesh Sharma | L23: CIO/Co-Founder | M23: mukesh@menterra.com | N23: https://www.linkedin.com/in/mukesh-sharma-ca-cfa-9b09475/ | O23: Farm Folks | P23: Direct | Q23: No
A24: C4D Partners | B24: Bangalore | C24: Bounced | D24: Bounced | E24: PE | F24: Has a separate fund investing in India (C4D Bharat Shubharambh Fund) | H24: =IFERROR((G24*1000000*$B$2)/10000000,0) -> 0 | J24: https://c4dpartners.com/ | K24: Arvind Agarwal | L24: CEO/Founder | M24: investments@c4dpartners.com | N24: https://www.linkedin.com/in/arvind-agarwal-in/ | O24: Aliet Green | P24: Direct | Q24: No
A25: Acumen | B25: USA | C25: 46163 | D25: Got response | E25: PE | F25: Invests in Indian agri companies | H25: =IFERROR((G25*1000000*$B$2)/10000000,0) -> 0 | J25: https://acumen.org/ | K25: Nidhisha Philip | L25: Manager | M25: nphilip@acumen.org | N25: https://www.linkedin.com/in/nidhisha-philip/ | O25: Kumaon Tea | P25: Secondary | Q25: No
A26: Aavishkaar Capital | B26: Mumbai | C26: 46163 | D26: 46191 | E26: PE/VC | F26: Invests in Indian agri companies; ticket size between $5-25m | H26: =IFERROR((G26*1000000*$B$2)/10000000,0) -> 0 | J26: https://aavishkaarcapital.in/ | K26: Harsh Kherajani | L26: Investment Professional | M26: harsh@aavishkaar.in | N26: https://www.linkedin.com/in/harsh-kherajani-461b01185/ | O26: Horizon Group | P26: Direct | Q26: No
A27: 8F Asset Management | B27: Singapore | C27: 46163 | D27: 46191 | E27: PE | F27: Invests in agri/acqua companies | H27: =IFERROR((G27*1000000*$B$2)/10000000,0) -> 0 | J27: https://8f-am.com/ | K27: N/A | L27: N/A | M27: contact@8f-am.com | N27: https://www.linkedin.com/company/8f-asset-management-pte-ltd/ | O27: N/A | P27: Secondary | Q27: No
A28: Ocean14 Capital | B28: UK | C28: 46163 | D28: 46191 | E28: PE/VC | F28: Invests in acqua companies with some Indian investments | H28: =IFERROR((G28*1000000*$B$2)/10000000,0) -> 0 | J28: https://ocean14capital.com/ | K28: Ricardo Cires | L28: Portfolio and Investments | M28: ricardo.cires@ocean14capital.com | N28: https://www.linkedin.com/in/ricardo-cires-a5348535/ | O28: N/A | P28: Secondary | Q28: No
A29: Proterra | B29: USA | C29: 46163 | D29: Got response | E29: PE | F29: Invests in Asian food production and processing brands | H29: =IFERROR((G29*1000000*$B$2)/10000000,0) -> 0 | J29: https://www.proterrapartners.com/ | K29: Eduardo Barros | L29: Director | M29: ebarros@proterrapartners.com | N29: https://www.linkedin.com/in/eduardo-barros-87606b17/ | O29: N/A | P29: Secondary | Q29: No
A30: responsAbility | B30: Switzerland | C30: 46163 | D30: 46191 | E30: PE | F30: Invests in Indian food and agri producers | H30: =IFERROR((G30*1000000*$B$2)/10000000,0) -> 0 | J30: https://www.responsability.com/ | K30: Akshay Dua | L30: Head of PE | M30: akshay.dua@responsability.com | N30: https://www.linkedin.com/in/akshay-dua-3626382/ | O30: Ace International | P30: Direct | Q30: No
A31: Seviora | B31: Singapore | C31: 46163 | D31: Got response | E31: PE | F31: Invests with an Asia focus with AM holding companies (Temasek holding) | H31: =IFERROR((G31*1000000*$B$2)/10000000,0) -> 0 | J31: https://www.sevioragroup.com/ | K31: Jeremy P. | L31: Investments | M31: jeremy.phua@sevioracapital.com | N31: https://www.linkedin.com/in/jeremyphua/ | O31: N/A | P31: Secondary | Q31: No
A32: Blue Earth Capital | B32: Switzerland | C32: 46163 | D32: 46191 | E32: PE/VC | F32: Invests in Indian agri companies | H32: =IFERROR((G32*1000000*$B$2)/10000000,0) -> 0 | J32: https://blueearth.capital/ | K32: Espen Haugen | L32: Investor | M32: espenugland.haugen@blueearth.capital | N32: https://www.linkedin.com/in/espen-ugland-haugen/ | O32: Captain Fresh | P32: Secondary | Q32: No
A33: British International Investment | B33: UK | C33: 46163 | D33: 46191 | E33: PE | F33: Invests in devoloping economies | H33: =IFERROR((G33*1000000*$B$2)/10000000,0) -> 0 | J33: https://www.bii.co.uk/en/ | K33: Vaibhav Soni | L33: Investment Executive | M33: vsoni@bii.co.uk | N33: https://www.linkedin.com/in/vaibhav-soni/ | O33: N/A | P33: Secondary | Q33: No
A34: Advent International | B34: USA | C34: 46163 | D34: 46191 | E34: PE | F34: Invests in consumer and B2B brands in India | H34: =IFERROR((G34*1000000*$B$2)/10000000,0) -> 0 | J34: https://www.adventinternational.com/ | K34: Mohammed Anjarwala | L34: Partner | M34: manjarwala@adventinternational.com | N34: https://www.linkedin.com/in/anjarwala/ | O34: DFM Foods | P34: Secondary | Q34: Yes
A35: Navis Capital Partners | B35: Malaysia | C35: 46167 | D35: 46181 | E35: PE | F35: Invests in Indian companies and food processing brands | H35: =IFERROR((G35*1000000*$B$2)/10000000,0) -> 0 | J35: https://www.naviscapital.com/ | K35: Gordon C. | L35: Operating Partner | M35: gchan@naviscapital.com | N35: https://www.linkedin.com/in/gordon-c-2118734/ | O35: Srithai | P35: Direct | Q35: Yes
A36: NAB Ventures | B36: Mumbai | C36: 46167 | D36: 46181 | E36: VC | F36: Invests in agri/food processing companies | H36: =IFERROR((G36*1000000*$B$2)/10000000,0) -> 0 | J36: https://nabventures.in/Default.aspx | K36: Vikas Bhatt | L36: Managing Director | M36: vbhatt@nabventures.com | N36: https://www.linkedin.com/in/vikas-bhatt-162bb810/ | O36: Fambo | P36: Direct | Q36: No
A37: Omnivore | B37: Mumbai | C37: 46168 | D37: 46182 | E37: VC | F37: Invests in food companies | H37: =IFERROR((G37*1000000*$B$2)/10000000,0) -> 0 | J37: https://omnivore.vc/ | K37: Reihem Roy | L37: Partner | M37: reihem@omnivore.vc | N37: https://www.linkedin.com/in/reihem/ | O37: Sid's Farm | P37: Secondary | Q37: No
A38: Evolvence Capital | B38: Mumbai | C38: 46168 | D38: 46182 | E38: PE/VC | F38: Invests in food companies | H38: =IFERROR((G38*1000000*$B$2)/10000000,0) -> 0 | J38: https://www.evolvenceequity.com/ | K38: Agrata Gupta | L38: Vice President | M38: agrata@evolvenceindia.com | N38: https://www.linkedin.com/in/agratagupta/ | O38: Captain Fresh | P38: Secondary | Q38: No
A39: Caspian Capital | B39: Hyderabad | C39: 46168 | D39: 46182 | E39: PE/VC | F39: Invests in food related companies and food processing | H39: =IFERROR((G39*1000000*$B$2)/10000000,0) -> 0 | J39: https://www.caspian.in/ | K39: Ravi Narasimham | L39: Managing Director | M39: ravinarasimham@caspian.in | N39: https://www.linkedin.com/in/ravi-narasimham/ | O39: Origo | P39: Secondary | Q39: No
A40: Ankur Capital | B40: Mumbai | C40: 46168 | D40: 46182 | E40: VC | F40: Invests in food related companies | H40: =IFERROR((G40*1000000*$B$2)/10000000,0) -> 0 | J40: https://www.ankurcapital.com/ | K40: Krishnan Neelakantan | L40: Partner | M40: krishnan@ankurcapital.com | N40: https://www.linkedin.com/in/krishnan-neelakantan-a429258/ | O40: Captain Fresh | P40: Secondary | Q40: No
A41: Rabo Investments | B41: Netherlands | C41: 46168 | D41: 46182 | E41: PE/VC | F41: Has an Indian arm | H41: =IFERROR((G41*1000000*$B$2)/10000000,0) -> 0 | J41: https://raboinvestments.com/ | K41: Pieter van der Meche | L41: Managing Director | M41: pieter.van.der.meche@rabobank.com | N41: https://www.linkedin.com/in/pvdmeche/ | O41: N/A | P41: Secondary | Q41: No
A42: Prosus Ventures | B42: Netherlands | C42: 46168 | D42: 46182 | E42: VC | F42: Invests in Indian food related companies | H42: =IFERROR((G42*1000000*$B$2)/10000000,0) -> 0 | J42: https://www.prosus.com/ | K42: Apoorve Goyal | L42: Managing Director | M42: apoorve.goyal@prosus.com | N42: https://www.linkedin.com/in/apoorve-goyal-67967797/ | O42: DeHaat | P42: Secondary | Q42: No
...

Sheet Company list 2
A1: [Client] target/buyer name
A2: Exchange rate as on date | B2: X
A3: =COUNTA(A7:A1048576) -> 0
A6: Company Name | B6: HQ | C6: Initial email | D6: Status | E6: Rationale | F6: Revenue from source | G6: Rev (INR Cr) | H6: Headcount | I6: Website link | J6: Contact Name | K6: Designation | L6: Email Id | M6: Linkedin | N6: Regarding
G7: =IFERROR((F7*1000000*$B$2)/10000000,0) -> 0
G8: =IFERROR((F8*1000000*$B$2)/10000000,0) -> 0
G9: =IFERROR((F9*1000000*$B$2)/10000000,0) -> 0
G10: =IFERROR((F10*1000000*$B$2)/10000000,0) -> 0
G11: =IFERROR((F11*1000000*$B$2)/10000000,0) -> 0
G12: =IFERROR((F12*1000000*$B$2)/10000000,0) -> 0
G13: =IFERROR((F13*1000000*$B$2)/10000000,0) -> 0
G14: =IFERROR((F14*1000000*$B$2)/10000000,0) -> 0
G15: =IFERROR((F15*1000000*$B$2)/10000000,0) -> 0
G16: =IFERROR((F16*1000000*$B$2)/10000000,0) -> 0
G17: =IFERROR((F17*1000000*$B$2)/10000000,0) -> 0
G18: =IFERROR((F18*1000000*$B$2)/10000000,0) -> 0
... G56: =IFERROR((F56*1000000*$B$2)/10000000,0) -> 0

Sheet Company list 3
A1: [Client] target/buyer name
A2: Exchange rate as on date | B2: X
A3: =COUNTA(A7:A1048576) -> 0
A6: Company Name | B6: HQ | C6: Initial email | D6: Status | E6: Rationale | F6: Revenue from source | G6: Rev (INR Cr) | H6: Headcount | I6: Website link | J6: Contact Name | K6: Designation | L6: Email Id | M6: Linkedin | N6: Regarding
G7: =IFERROR((F7*1000000*$B$2)/10000000,0) -> 0
G8: =IFERROR((F8*1000000*$B$2)/10000000,0) -> 0
G9: =IFERROR((F9*1000000*$B$2)/10000000,0) -> 0
G10: =IFERROR((F10*1000000*$B$2)/10000000,0) -> 0
G11: =IFERROR((F11*1000000*$B$2)/10000000,0) -> 0
G12: =IFERROR((F12*1000000*$B$2)/10000000,0) -> 0
G13: =IFERROR((F13*1000000*$B$2)/10000000,0) -> 0
G14: =IFERROR((F14*1000000*$B$2)/10000000,0) -> 0
G15: =IFERROR((F15*1000000*$B$2)/10000000,0) -> 0
G16: =IFERROR((F16*1000000*$B$2)/10000000,0) -> 0
G17: =IFERROR((F17*1000000*$B$2)/10000000,0) -> 0
G18: =IFERROR((F18*1000000*$B$2)/10000000,0) -> 0
... G56: =IFERROR((F56*1000000*$B$2)/10000000,0) -> 0

Sheet Emailing schedule
A1: Next set of emails due in (days) | C1: =MIN(J7:M76) -> 3 | D1: Count | E1: =SUBTOTAL(3,A7:A1048576) -> 70
D2: Check | E2: =E1-'Company list 1'!A3-'Company list 2'!A3-'Company list 3'!A3 -> 0
B5: =IF(COUNTIF(B7:B1048576,"Error")>0,"Error", "Go") -> Go | C5: =IF(COUNTIF(C7:C1048576,"Error")>0,"Error", "Go") -> Go | E5: =IF(COUNTIF(E7:E1048576,"Error")>0,"Error", "Go") -> Go
A6: Company name | B6: Check to previous sheets | C6: Regarding | D6: Initial date | E6: Status | F6: Bi-weekly follow up | G6: Bi-weekly follow up | H6: Bi-weekly follow up | I6: Bi-weekly follow up | J6: Follow ups (in days)
A7: Mandala Capital | B7: =IFERROR(IF(COUNTIF('Company list 1'!$A$7:$A$1048576,A7)+COUNTIF('Company list 2'!$A$7:$A$1048576,A7)+COUNTIF('Company list 3'!$A$7:$A$1048576, A7)=1, "Yes", "Error"),"Error") -> Yes | D7: =_xlfn.LET(_xlpm.L,IFERROR(_xlfn.XLOOKUP(A7,#REF!,#REF!),_xlfn.XLOOKUP(A7,'Company list 1'!A:A,'Company list 1'!C:C,"")),IF(_xlpm.L=0,"",_xlpm.L)) -> 46160 | E7: =_xlfn.LET(_xlpm.d,IFERROR(_xlfn.XLOOKUP(A7,#REF!,#REF!),_xlfn.XLOOKUP(A7,'Company list 1'!A:A,'Company list 1'!D:D,"")),IF(_xlpm.d=0,"",_xlpm.d)) -> Got response | F7: =IF(ISNUMBER($E7),D7+14,"") | G7: =IF(ISNUMBER($E7),F7+14,"") | H7: =IF(ISNUMBER($E7),G7+14,"") | I7: =IF(ISNUMBER($E7),H7+14,"") | J7: =IF(NOT(ISNUMBER($E7)),"",IF($E7>=F7,"Done",F7-TODAY())) | K7: =IF(NOT(ISNUMBER($E7)),"",IF($E7>=G7,"Done",G7-TODAY())) | L7: =IF(NOT(ISNUMBER($E7)),"",IF($E7>=H7,"Done",H7-TODAY())) | M7: =IF(NOT(ISNUMBER($E7)),"",IF($E7>=I7,"Done",I7-TODAY()))
A8: JM Financial | B8: =IFERROR(IF(COUNTIF('Company list 1'!$A$7:$A$1048576,A8)+COUNTIF('Company list 2'!$A$7:$A$1048576,A8)+COUNTIF('Company list 3'!$A$7:$A$1048576, A8)=1, "Yes", "Error"),"Error") -> Yes | D8: =_xlfn.LET(_xlpm.L,IFERROR(_xlfn.XLOOKUP(A8,#REF!,#REF!),_xlfn.XLOOKUP(A8,'Company list 1'!A:A,'Company list 1'!C:C,"")),IF(_xlpm.L=0,"",_xlpm.L)) -> 46160 | E8: =_xlfn.LET(_xlpm.d,IFERROR(_xlfn.XLOOKUP(A8,#REF!,#REF!),_xlfn.XLOOKUP(A8,'Company list 1'!A:A,'Company list 1'!D:D,"")),IF(_xlpm.d=0,"",_xlpm.d)) -> Got response | F8: =IF(ISNUMBER($E8),D8+14,"") | G8: =IF(ISNUMBER($E8),F8+14,"") | H8: =IF(ISNUMBER($E8),G8+14,"") | I8: =IF(ISNUMBER($E8),H8+14,"") | J8: =IF(NOT(ISNUMBER($E8)),"",IF($E8>=F8,"Done",F8-TODAY())) | K8: =IF(NOT(ISNUMBER($E8)),"",IF($E8>=G8,"Done",G8-TODAY())) | L8: =IF(NOT(ISNUMBER($E8)),"",IF($E8>=H8,"Done",H8-TODAY())) | M8: =IF(NOT(ISNUMBER($E8)),"",IF($E8>=I8,"Done",I8-TODAY()))
A9: Catamaran Ventures | B9: =IFERROR(IF(COUNTIF('Company list 1'!$A$7:$A$1048576,A9)+COUNTIF('Company list 2'!$A$7:$A$1048576,A9)+COUNTIF('Company list 3'!$A$7:$A$1048576, A9)=1, "Yes", "Error"),"Error") -> Yes | D9: =_xlfn.LET(_xlpm.L,IFERROR(_xlfn.XLOOKUP(A9,#REF!,#REF!),_xlfn.XLOOKUP(A9,'Company list 1'!A:A,'Company list 1'!C:C,"")),IF(_xlpm.L=0,"",_xlpm.L)) -> 46160 | E9: =_xlfn.LET(_xlpm.d,IFERROR(_xlfn.XLOOKUP(A9,#REF!,#REF!),_xlfn.XLOOKUP(A9,'Company list 1'!A:A,'Company list 1'!D:D,"")),IF(_xlpm.d=0,"",_xlpm.d)) -> Got response | F9: =IF(ISNUMBER($E9),D9+14,"") | G9: =IF(ISNUMBER($E9),F9+14,"") | H9: =IF(ISNUMBER($E9),G9+14,"") | I9: =IF(ISNUMBER($E9),H9+14,"") | J9: =IF(NOT(ISNUMBER($E9)),"",IF($E9>=F9,"Done",F9-TODAY())) | K9: =IF(NOT(ISNUMBER($E9)),"",IF($E9>=G9,"Done",G9-TODAY())) | L9: =IF(NOT(ISNUMBER($E9)),"",IF($E9>=H9,"Done",H9-TODAY())) | M9: =IF(NOT(ISNUMBER($E9)),"",IF($E9>=I9,"Done",I9-TODAY()))
A10: Convergent Finance | B10: =IFERROR(IF(COUNTIF('Company list 1'!$A$7:$A$1048576,A10)+COUNTIF('Company list 2'!$A$7:$A$1048576,A10)+COUNTIF('Company list 3'!$A$7:$A$1048576, A10)=1, "Yes", "Error"),"Error") -> Yes | D10: =_xlfn.LET(_xlpm.L,IFERROR(_xlfn.XLOOKUP(A10,#REF!,#REF!),_xlfn.XLOOKUP(A10,'Company list 1'!A:A,'Company list 1'!C:C,"")),IF(_xlpm.L=0,"",_xlpm.L)) -> 46160 | E10: =_xlfn.LET(_xlpm.d,IFERROR(_xlfn.XLOOKUP(A10,#REF!,#REF!),_xlfn.XLOOKUP(A10,'Company list 1'!A:A,'Company list 1'!D:D,"")),IF(_xlpm.d=0,"",_xlpm.d)) -> Got response | F10: =IF(ISNUMBER($E10),D10+14,"") | G10: =IF(ISNUMBER($E10),F10+14,"") | H10: =IF(ISNUMBER($E10),G10+14,"") | I10: =IF(ISNUMBER($E10),H10+14,"") | J10: =IF(NOT(ISNUMBER($E10)),"",IF($E10>=F10,"Done",F10-TODAY())) | K10: =IF(NOT(ISNUMBER($E10)),"",IF($E10>=G10,"Done",G10-TODAY())) | L10: =IF(NOT(ISNUMBER($E10)),"",IF($E10>=H10,"Done",H10-TODAY())) | M10: =IF(NOT(ISNUMBER($E10)),"",IF($E10>=I10,"Done",I10-TODAY()))
A11: Sharrp Ventures | B11: =IFERROR(IF(COUNTIF('Company list 1'!$A$7:$A$1048576,A11)+COUNTIF('Company list 2'!$A$7:$A$1048576,A11)+COUNTIF('Company list 3'!$A$7:$A$1048576, A11)=1, "Yes", "Error"),"Error") -> Yes | D11: =_xlfn.LET(_xlpm.L,IFERROR(_xlfn.XLOOKUP(A11,#REF!,#REF!),_xlfn.XLOOKUP(A11,'Company list 1'!A:A,'Company list 1'!C:C,"")),IF(_xlpm.L=0,"",_xlpm.L)) -> 46160 | E11: =_xlfn.LET(_xlpm.d,IFERROR(_xlfn.XLOOKUP(A11,#REF!,#REF!),_xlfn.XLOOKUP(A11,'Company list 1'!A:A,'Company list 1'!D:D,"")),IF(_xlpm.d=0,"",_xlpm.d)) -> 46188 | F11: =IF(ISNUMBER($E11),D11+14,"") -> 46174 | G11: =IF(ISNUMBER($E11),F11+14,"") -> 46188 | H11: =IF(ISNUMBER($E11),G11+14,"") -> 46202 | I11: =IF(ISNUMBER($E11),H11+14,"") -> 46216 | J11: =IF(NOT(ISNUMBER($E11)),"",IF($E11>=F11,"Done",F11-TODAY())) -> Done | K11: =IF(NOT(ISNUMBER($E11)),"",IF($E11>=G11,"Done",G11-TODAY())) -> Done | L11: =IF(NOT(ISNUMBER($E11)),"",IF($E11>=H11,"Done",H11-TODAY())) -> 10 | M11: =IF(NOT(ISNUMBER($E11)),"",IF($E11>=I11,"Done",I11-TODAY())) -> 24
A12: DS Group | B12: =IFERROR(IF(COUNTIF('Company list 1'!$A$7:$A$1048576,A12)+COUNTIF('Company list 2'!$A$7:$A$1048576,A12)+COUNTIF('Company list 3'!$A$7:$A$1048576, A12)=1, "Yes", "Error"),"Error") -> Yes | D12: =_xlfn.LET(_xlpm.L,IFERROR(_xlfn.XLOOKUP(A12,#REF!,#REF!),_xlfn.XLOOKUP(A12,'Company list 1'!A:A,'Company list 1'!C:C,"")),IF(_xlpm.L=0,"",_xlpm.L)) -> 46160 | E12: =_xlfn.LET(_xlpm.d,IFERROR(_xlfn.XLOOKUP(A12,#REF!,#REF!),_xlfn.XLOOKUP(A12,'Company list 1'!A:A,'Company list 1'!D:D,"")),IF(_xlpm.d=0,"",_xlpm.d)) -> 46188 | F12: =IF(ISNUMBER($E12),D12+14,"") -> 46174 | G12: =IF(ISNUMBER($E12),F12+14,"") -> 46188 | H12: =IF(ISNUMBER($E12),G12+14,"") -> 46202 | I12: =IF(ISNUMBER($E12),H12+14,"") -> 46216 | J12: =IF(NOT(ISNUMBER($E12)),"",IF($E12>=F12,"Done",F12-TODAY())) -> Done | K12: =IF(NOT(ISNUMBER($E12)),"",IF($E12>=G12,"Done",G12-TODAY())) -> Done | L12: =IF(NOT(ISNUMBER($E12)),"",IF($E12>=H12,"Done",H12-TODAY())) -> 10 | M12: =IF(NOT(ISNUMBER($E12)),"",IF($E12>=I12,"Done",I12-TODAY())) -> 24
A13: RP Sanjiv Goenka Family Office | B13: =IFERROR(IF(COUNTIF('Company list 1'!$A$7:$A$1048576,A13)+COUNTIF('Company list 2'!$A$7:$A$1048576,A13)+COUNTIF('Company list 3'!$A$7:$A$1048576, A13)=1, "Yes", "Error"),"Error") -> Yes | D13: =_xlfn.LET(_xlpm.L,IFERROR(_xlfn.XLOOKUP(A13,#REF!,#REF!),_xlfn.XLOOKUP(A13,'Company list 1'!A:A,'Company list 1'!C:C,"")),IF(_xlpm.L=0,"",_xlpm.L)) -> 46160 | E13: =_xlfn.LET(_xlpm.d,IFERROR(_xlfn.XLOOKUP(A13,#REF!,#REF!),_xlfn.XLOOKUP(A13,'Company list 1'!A:A,'Company list 1'!D:D,"")),IF(_xlpm.d=0,"",_xlpm.d)) -> Got response | F13: =IF(ISNUMBER($E13),D13+14,"") | G13: =IF(ISNUMBER($E13),F13+14,"") | H13: =IF(ISNUMBER($E13),G13+14,"") | I13: =IF(ISNUMBER($E13),H13+14,"") | J13: =IF(NOT(ISNUMBER($E13)),"",IF($E13>=F13,"Done",F13-TODAY())) | K13: =IF(NOT(ISNUMBER($E13)),"",IF($E13>=G13,"Done",G13-TODAY())) | L13: =IF(NOT(ISNUMBER($E13)),"",IF($E13>=H13,"Done",H13-TODAY())) | M13: =IF(NOT(ISNUMBER($E13)),"",IF($E13>=I13,"Done",I13-TODAY()))
A14: Negen Capital | B14: =IFERROR(IF(COUNTIF('Company list 1'!$A$7:$A$1048576,A14)+COUNTIF('Company list 2'!$A$7:$A$1048576,A14)+COUNTIF('Company list 3'!$A$7:$A$1048576, A14)=1, "Yes", "Error"),"Error") -> Yes | D14: =_xlfn.LET(_xlpm.L,IFERROR(_xlfn.XLOOKUP(A14,#REF!,#REF!),_xlfn.XLOOKUP(A14,'Company list 1'!A:A,'Company list 1'!C:C,"")),IF(_xlpm.L=0,"",_xlpm.L)) -> 46160 | E14: =_xlfn.LET(_xlpm.d,IFERROR(_xlfn.XLOOKUP(A14,#REF!,#REF!),_xlfn.XLOOKUP(A14,'Company list 1'!A:A,'Company list 1'!D:D,"")),IF(_xlpm.d=0,"",_xlpm.d)) -> 46188 | F14: =IF(ISNUMBER($E14),D14+14,"") -> 46174 | G14: =IF(ISNUMBER($E14),F14+14,"") -> 46188 | H14: =IF(ISNUMBER($E14),G14+14,"") -> 46202 | I14: =IF(ISNUMBER($E14),H14+14,"") -> 46216 | J14: =IF(NOT(ISNUMBER($E14)),"",IF($E14>=F14,"Done",F14-TODAY())) -> Done | K14: =IF(NOT(ISNUMBER($E14)),"",IF($E14>=G14,"Done",G14-TODAY())) -> Done | L14: =IF(NOT(ISNUMBER($E14)),"",IF($E14>=H14,"Done",H14-TODAY())) -> 10 | M14: =IF(NOT(ISNUMBER($E14)),"",IF($E14>=I14,"Done",I14-TODAY())) -> 24
A15: Lighthouse Funds | B15: =IFERROR(IF(COUNTIF('Company list 1'!$A$7:$A$1048576,A15)+COUNTIF('Company list 2'!$A$7:$A$1048576,A15)+COUNTIF('Company list 3'!$A$7:$A$1048576, A15)=1, "Yes", "Error"),"Error") -> Yes | D15: =_xlfn.LET(_xlpm.L,IFERROR(_xlfn.XLOOKUP(A15,#REF!,#REF!),_xlfn.XLOOKUP(A15,'Company list 1'!A:A,'Company list 1'!C:C,"")),IF(_xlpm.L=0,"",_xlpm.L)) -> 46160 | E15: =_xlfn.LET(_xlpm.d,IFERROR(_xlfn.XLOOKUP(A15,#REF!,#REF!),_xlfn.XLOOKUP(A15,'Company list 1'!A:A,'Company list 1'!D:D,"")),IF(_xlpm.d=0,"",_xlpm.d)) -> 46188 | F15: =IF(ISNUMBER($E15),D15+14,"") -> 46174 | G15: =IF(ISNUMBER($E15),F15+14,"") -> 46188 | H15: =IF(ISNUMBER($E15),G15+14,"") -> 46202 | I15: =IF(ISNUMBER($E15),H15+14,"") -> 46216 | J15: =IF(NOT(ISNUMBER($E15)),"",IF($E15>=F15,"Done",F15-TODAY())) -> Done | K15: =IF(NOT(ISNUMBER($E15)),"",IF($E15>=G15,"Done",G15-TODAY())) -> Done | L15: =IF(NOT(ISNUMBER($E15)),"",IF($E15>=H15,"Done",H15-TODAY())) -> 10 | M15: =IF(NOT(ISNUMBER($E15)),"",IF($E15>=I15,"Done",I15-TODAY())) -> 24
A16: Carpediem Capital | B16: =IFERROR(IF(COUNTIF('Company list 1'!$A$7:$A$1048576,A16)+COUNTIF('Company list 2'!$A$7:$A$1048576,A16)+COUNTIF('Company list 3'!$A$7:$A$1048576, A16)=1, "Yes", "Error"),"Error") -> Yes | D16: =_xlfn.LET(_xlpm.L,IFERROR(_xlfn.XLOOKUP(A16,#REF!,#REF!),_xlfn.XLOOKUP(A16,'Company list 1'!A:A,'Company list 1'!C:C,"")),IF(_xlpm.L=0,"",_xlpm.L)) -> 46160 | E16: =_xlfn.LET(_xlpm.d,IFERROR(_xlfn.XLOOKUP(A16,#REF!,#REF!),_xlfn.XLOOKUP(A16,'Company list 1'!A:A,'Company list 1'!D:D,"")),IF(_xlpm.d=0,"",_xlpm.d)) -> Got response | F16: =IF(ISNUMBER($E16),D16+14,"") | G16: =IF(ISNUMBER($E16),F16+14,"") | H16: =IF(ISNUMBER($E16),G16+14,"") | I16: =IF(ISNUMBER($E16),H16+14,"") | J16: =IF(NOT(ISNUMBER($E16)),"",IF($E16>=F16,"Done",F16-TODAY())) | K16: =IF(NOT(ISNUMBER($E16)),"",IF($E16>=G16,"Done",G16-TODAY())) | L16: =IF(NOT(ISNUMBER($E16)),"",IF($E16>=H16,"Done",H16-TODAY())) | M16: =IF(NOT(ISNUMBER($E16)),"",IF($E16>=I16,"Done",I16-TODAY()))
A17: Narotam Sekhsaria Family Office | B17: =IFERROR(IF(COUNTIF('Company list 1'!$A$7:$A$1048576,A17)+COUNTIF('Company list 2'!$A$7:$A$1048576,A17)+COUNTIF('Company list 3'!$A$7:$A$1048576, A17)=1, "Yes", "Error"),"Error") -> Yes | D17: =_xlfn.LET(_xlpm.L,IFERROR(_xlfn.XLOOKUP(A17,#REF!,#REF!),_xlfn.XLOOKUP(A17,'Company list 1'!A:A,'Company list 1'!C:C,"")),IF(_xlpm.L=0,"",_xlpm.L)) -> 46160 | E17: =_xlfn.LET(_xlpm.d,IFERROR(_xlfn.XLOOKUP(A17,#REF!,#REF!),_xlfn.XLOOKUP(A17,'Company list 1'!A:A,'Company list 1'!D:D,"")),IF(_xlpm.d=0,"",_xlpm.d)) -> Got response | F17: =IF(ISNUMBER($E17),D17+14,"") | G17: =IF(ISNUMBER($E17),F17+14,"") | H17: =IF(ISNUMBER($E17),G17+14,"") | I17: =IF(ISNUMBER($E17),H17+14,"") | J17: =IF(NOT(ISNUMBER($E17)),"",IF($E17>=F17,"Done",F17-TODAY())) | K17: =IF(NOT(ISNUMBER($E17)),"",IF($E17>=G17,"Done",G17-TODAY())) | L17: =IF(NOT(ISNUMBER($E17)),"",IF($E17>=H17,"Done",H17-TODAY())) | M17: =IF(NOT(ISNUMBER($E17)),"",IF($E17>=I17,"Done",I17-TODAY()))
A18: Anicut Capital | B18: =IFERROR(IF(COUNTIF('Company list 1'!$A$7:$A$1048576,A18)+COUNTIF('Company list 2'!$A$7:$A$1048576,A18)+COUNTIF('Company list 3'!$A$7:$A$1048576, A18)=1, "Yes", "Error"),"Error") -> Yes | D18: =_xlfn.LET(_xlpm.L,IFERROR(_xlfn.XLOOKUP(A18,#REF!,#REF!),_xlfn.XLOOKUP(A18,'Company list 1'!A:A,'Company list 1'!C:C,"")),IF(_xlpm.L=0,"",_xlpm.L)) -> Priya Mam reach out | E18: =_xlfn.LET(_xlpm.d,IFERROR(_xlfn.XLOOKUP(A18,#REF!,#REF!),_xlfn.XLOOKUP(A18,'Company list 1'!A:A,'Company list 1'!D:D,"")),IF(_xlpm.d=0,"",_xlpm.d)) -> Priya Mam reach out | F18: =IF(ISNUMBER($E18),D18+14,"") | G18: =IF(ISNUMBER($E18),F18+14,"") | H18: =IF(ISNUMBER($E18),G18+14,"") | I18: =IF(ISNUMBER($E18),H18+14,"") | J18: =IF(NOT(ISNUMBER($E18)),"",IF($E18>=F18,"Done",F18-TODAY())) | K18: =IF(NOT(ISNUMBER($E18)),"",IF($E18>=G18,"Done",G18-TODAY())) | L18: =IF(NOT(ISNUMBER($E18)),"",IF($E18>=H18,"Done",H18-TODAY())) | M18: =IF(NOT(ISNUMBER($E18)),"",IF($E18>=I18,"Done",I18-TODAY()))
... A76: Al Dahra | B76: =IFERROR(IF(COUNTIF('Company list 1'!$A$7:$A$1048576,A76)+COUNTIF('Company list 2'!$A$7:$A$1048576,A76)+COUNTIF('Company list 3'!$A$7:$A$1048576, A76)=1, "Yes", "Error"),"Error") -> Yes | D76: =_xlfn.LET(_xlpm.L,IFERROR(_xlfn.XLOOKUP(A76,#REF!,#REF!),_xlfn.XLOOKUP(A76,'Company list 1'!A:A,'Company list 1'!C:C,"")),IF(_xlpm.L=0,"",_xlpm.L)) -> 46174 | E76: =_xlfn.LET(_xlpm.d,IFERROR(_xlfn.XLOOKUP(A76,#REF!,#REF!),_xlfn.XLOOKUP(A76,'Company list 1'!A:A,'Company list 1'!D:D,"")),IF(_xlpm.d=0,"",_xlpm.d)) -> Bounced | F76: =IF(ISNUMBER($E76),D76+14,"") | G76: =IF(ISNUMBER($E76),F76+14,"") | H76: =IF(ISNUMBER($E76),G76+14,"") | I76: =IF(ISNUMBER($E76),H76+14,"") | J76: =IF(NOT(ISNUMBER($E76)),"",IF($E76>=F76,"Done",F76-TODAY())) | K76: =IF(NOT(ISNUMBER($E76)),"",IF($E76>=G76,"Done",G76-TODAY())) | L76: =IF(NOT(ISNUMBER($E76)),"",IF($E76>=H76,"Done",H76-TODAY())) | M76: =IF(NOT(ISNUMBER($E76)),"",IF($E76>=I76,"Done",I76-TODAY()))
