Workbook

Sheet Master sheets and emailers >>>
B3: Ongoing | C3: Got response | D3: Bounced | E3: Total | F3: Response rate
A4: PE | B4: =COUNT('PE names final'!$D:$D) -> 47 | C4: =COUNTIF('PE names final'!$D:$D,"Got response") -> 21 | D4: =COUNTIF('PE names final'!$D:$D,"Bounced") -> 2 | E4: =SUM(B4:D4) -> 70 | F4: =IFERROR(C4/E4,0) -> 0.3
A5: PE porfolio | B5: =COUNT('PE porfolio names final'!$D:$D) -> 32 | C5: =COUNTIF('PE porfolio names final'!$D:$D,"Got response") -> 15 | D5: =COUNTIF('PE porfolio names final'!$D:$D,"Bounced") -> 6 | E5: =SUM(B5:D5) -> 53 | F5: =IFERROR(C5/E5,0) -> 0.28301887
A6: Total | B6: =SUM(B4:B5) -> 79 | C6: =SUM(C4:C5) -> 36 | D6: =SUM(D4:D5) -> 8 | E6: =SUM(E4:E5) -> 123 | F6: =IFERROR(C6/E6,0) -> 0.29268293

Sheet PE names final
A1: PE porfotio buyers - 22by7
A2: =COUNTA(A6:A1048576) -> 70
A5: Company Name | B5: HQ | C5: Initial email | D5: Status | E5: Website link | F5: Contact Name 1 | G5: Designation 1 | H5: Email Id 1 | I5: Linkedin 1 | J5: Contact Name 2 | K5: Designation 2 | L5: Email Id 2 | M5: Linkedin 2 | N5: Bucket
A6: Trunorth | B6: India | C6: 46034 | D6: 46091 | E6: https://www.truenorth.co.in/ | F6: Mahinder Singh Juneja | G6: Partner | H6: maninder@truenorth.co.in | I6: https://www.linkedin.com/in/maninder-singh-juneja-35a01a13/ | J6: Khushal Singla | K6: Private Credit Investment Professional | L6: khushal@truenorth.co.in | M6: https://www.linkedin.com/in/khushal-singla-656017166/ | N6: Indian PEs with related porfolio companies
A7: MC Partners | B7: USA | C7: 46055 | D7: Got response | E7: https://www.mcpartners.com/ | F7: Ryan Carr | G7: Partner | H7: rcarr@mcpartners.com | I7: https://www.linkedin.com/in/ryan-carr-b6453736/ | N7: Foreign PEs with related pofolio companies having Indian offices
A8: Norwest | B8: USA | C8: 46051 | D8: 46107 | E8: https://www.norwest.com/ | F8: Jon Kossow | G8: Managing Partner | H8: jkossow@nvp.com | I8: https://www.linkedin.com/in/jon-kossow-42706b2/ | N8: Foreign PEs with related pofolio companies having Indian offices
A9: Intel Capital | B9: USA | C9: 46051 | D9: 46107 | E9: https://www.intelcapital.com/ | F9: Aravind Bharadwaj | G9: Investment Partner | H9: aravind.bharadwaj@intel.com | I9: https://www.linkedin.com/in/aravindbharadwaj/ | N9: Foreign PEs with related pofolio companies having Indian offices
A10: The Stephens Group | B10: USA | C10: 46043 | D10: 46099 | E10: https://www.stephensgroup.com/ | F10: Jack Nadal | G10: Managing Director | H10: jnadal@stephensgroup.com | I10: https://www.linkedin.com/in/jack-nadal-7157b8a/ | N10: Foreign PEs with related pofolio companies having Indian offices
A11: VSS Capital Partners | B11: USA | C11: 46062 | D11: 46120 | E11: https://www.vss.com/ | F11: Jeffrey Stevenson | G11: Managing Partner | H11: stevensonj@vss.com | I11: https://www.linkedin.com/in/jeffrey-stevenson-8914318/ | N11: Foreign PEs with related pofolio companies having Indian offices
A12: Abry Partners | B12: USA | C12: 46051 | D12: 46107 | E12: https://abry.com/ | F12: Vidur Khatri | G12: Principal | H12: vkhatri@abry.com | I12: https://www.linkedin.com/in/vidur-khatri-52aa0946/ | N12: Foreign PEs with related pofolio companies having Indian offices
A13: Lightview Partners | B13: USA | C13: 46062 | D13: 46120 | E13: https://www.lightviewcapital.com/ | F13: Conor Mullett | G13: Co-Founder/Managing Director | H13: cmullett@lightviewcapital.com | I13: https://www.linkedin.com/in/conor-mullett-7b640b/ | N13: Foreign PEs with related pofolio companies having Indian offices
A14: Recognize | B14: USA | C14: 46062 | D14: Bounced | E14: https://recognize.com/ | F14: Muthu Kumaran | G14: Head of India Operations/Operating Partner | H14: muthu@recognize.com | I14: https://www.linkedin.com/in/muthu-kumaran-a616a616/ | N14: Foreign PEs with related pofolio companies having Indian offices
A15: Advent | B15: USA | C15: 46035 | D15: 46091 | E15: https://www.adventinternational.com/ | F15: Mohammed Anjarwala | G15: Partner | H15: manjarwala@adventinternational.com | I15: https://www.linkedin.com/in/anjarwala/ | N15: Foreign PE with potfolio companies not having Indian offices
A16: Kedaara | B16: India | C16: 46034 | D16: Got response | E16: https://kedaara.com/ | F16: Manish Kejriwal | G16: Founder/Managing Partner | H16: manish.kejriwal@kedaara.com | I16: https://www.linkedin.com/in/manish-kejriwal-1a7336/ | J16: Priyansh Changoiwala | K16: Associate | L16: priyansh.changoiwala@kedaara.com | M16: https://www.linkedin.com/in/priyansh-changoiwala-685280177/ | N16: Indian PE with unrelated potfolio companies
A17: 8 Roads | B17: Bermuda | C17: 46055 | D17: 46111 | E17: https://eightroads.com/en/ | F17: Gordon Zhang | G17: Partner | H17: gordon.zhang@eightroads.com | I17: https://www.linkedin.com/in/gordon-zhang-9490b3273/ | N17: Foreign PE with potfolio companies not having Indian offices
A18: Convergent Finance | B18: India | C18: 46034 | D18: 46091 | E18: https://convergentfinance.com/ | F18: Harsha Raghavan | G18: Managing Partner | H18: harsha@convergentfinance.com | I18: https://www.linkedin.com/in/harsha-raghavan-1218a11b5/ | N18: Indian PEs with unrelated potfolio companies
A19: Premji Invest | B19: India | C19: 46034 | D19: 46091 | E19: https://in.premjiinvest.com/ | F19: Kaveesh Chawla | G19: Partner | H19: kaveesh.chawla@premjiinvest.com | I19: https://www.linkedin.com/in/kaveeshchawla/ | N19: Indian PEs with unrelated potfolio companies
A20: Samara Capital | B20: India | C20: 46034 | D20: Got response | E20: https://samaracapital.com/ | F20: Manish Mehta | G20: Managing Director | H20: manish@samaracapital.com | I20: https://www.linkedin.com/in/manish-mehta-0883873/ | N20: Indian PEs with unrelated potfolio companies
A21: Evergreen Services Group | B21: USA | C21: 45974 | D21: Got response | E21: https://www.evergreensg.com/ | F21: Ramsey Sahyoun | G21: Co-founder/M&A Partner | H21: rsahyoun@evergreensg.com | I21: https://www.linkedin.com/in/ramsey-sahyoun-67b32683/ | N21: Foreign PE with potfolio companies not having Indian offices
A22: Creador | B22: Malysia | C22: 46055 | D22: 46111 | E22: https://creador.com/ | F22: Alberto Lazzari | G22: PE Professional | H22: a.lazzari@creador.com | I22: https://www.linkedin.com/in/alberto-lazzari-mba-217b944a/ | N22: Foreign PE with potfolio companies not having Indian offices
A23: Sunstone Partners | B23: USA | C23: 45974 | D23: Got response | E23: https://sunstonepartners.com/ | F23: Ankur Rathi | G23: Partner | H23: arathi@sunstonepartners.com | I23: https://www.linkedin.com/in/arathi2/ | N23: Foreign PE with potfolio companies not having Indian offices
A24: ChrysCapital | B24: Mauritius | C24: 46055 | D24: 46111 | E24: https://chryscapital.com/ | F24: Sanjiv Kaul | G24: Partner | H24: sanjiv@chryscapital.com | I24: https://www.linkedin.com/in/sanjiv-kaul-135b301a5/ | N24: Foreign PE with potfolio companies not having Indian offices
A25: Halyard Capital | B25: USA | C25: 46055 | D25: 46111 | E25: https://www.halyard.com/ | F25: Robert Nolan | G25: Managing Partner | H25: rnolan@halyard.com | I25: https://www.linkedin.com/in/robert-nolan10/ | N25: Foreign PE with potfolio companies not having Indian offices
A26: Navis Capital Partners | B26: Malaysia | C26: 46055 | D26: Got response | E26: https://www.naviscapital.com/ | F26: Gordon C. | G26: Operating Partner | H26: gchan@naviscapital.com | I26: https://www.linkedin.com/in/gordon-c-2118734/ | N26: Foreign PE with potfolio companies not having Indian offices
A27: Ascent Capital | B27: India | C27: 46034 | D27: 46091 | E27: https://ascentcapital.in/ | F27: Raja Kumar | G27: Founder/Managing Partner | H27: raja@ascentcapital.in | I27: https://www.linkedin.com/in/raja-kumar-455b7245/ | N27: Indian PEs with unrelated potfolio companies
A28: Gaja Capital | B28: India | C28: 46034 | D28: Got response | E28: https://gajacapital.com/ | F28: Sushane Chopra | G28: Partner | H28: sushane.chopra@gajacapital.com | I28: https://www.linkedin.com/in/sushane-chopra-b248334/ | N28: Indian PEs with unrelated potfolio companies
A29: Westbridge Capital | B29: India | C29: 46034 | D29: 46091 | E29: https://westbridgecap.com/ | F29: Sumir Chadha | G29: Co-founder/Managing Partner | H29: sumir.chadha@westbridgecap.com | I29: https://www.linkedin.com/in/sumir-chadha-bb8b563/ | N29: Indian PEs with unrelated potfolio companies
A30: Stakeboat Capital | B30: India | C30: 46034 | D30: Got response | E30: https://stakeboat.com/ | F30: Chandrasekar Kandasamy | G30: Managing Partner | H30: chandra@stakeboat.com | I30: https://www.linkedin.com/in/chandrasekar-kandasamy-4b8703/ | J30: Ram Pratheek Azendla | K30: Senior Associate | L30: pratheek@stakeboat.com | M30: https://www.linkedin.com/in/rampratheek/ | N30: Indian PEs with unrelated potfolio companies
A31: Prosperity7 Ventures | B31: Saudi Arabia | C31: 46055 | D31: 46111 | E31: https://www.prosperity7vc.com/ | F31: Abhishek Shukla | G31: Managing Director and Head of North America | H31: abhishek.shukla@p7vc.com | I31: https://www.linkedin.com/in/ashukla1/ | N31: Foreign PE with potfolio companies not having Indian offices
A32: Steadview Capital | B32: UK | C32: 46062 | D32: 46120 | E32: https://www.steadview.com/ | F32: Joy Bhakat | G32: Co-Founder/Head of Investments | H32: jbhakat@steadview.com | I32: https://www.linkedin.com/in/joy-bhakat-35895845/ | N32: Foreign PE with potfolio companies not having Indian offices
A33: Avataar Ventures | B33: India | C33: 46034 | D33: Got response | E33: https://www.avataar.vc/ | F33: Arjun Vikas | G33: Director | H33: arjun@avataar.vc | I33: https://www.linkedin.com/in/arjun-vikas-84118849/ | N33: Indian PEs with unrelated potfolio companies
A34: Affirma Capital | B34: Singapore | C34: 46062 | D34: Got response | E34: https://affirmacapital.com/ | F34: Ivo Philipps | G34: COO/Founding Partner | H34: ivo.philipps@affirmacapital.com | I34: https://www.linkedin.com/in/ivo-philipps-5a74244/ | N34: Foreign PE with potfolio companies having Indian offices
A35: Investcorp | B35: Bahrain | C35: 46034 | D35: 46091 | E35: https://www.investcorp.com/ | F35: Anshuman Goenka | G35: Partner | H35: agoenka@investcorp.com | I35: https://www.linkedin.com/in/anshuman-goenka-319435/ | N35: Indian PEs with unrelated potfolio companies
A36: BGF | B36: UK | C36: 46062 | D36: 46120 | E36: https://www.bgf.co.uk/ | F36: Pinesh Mehta | G36: Partner | H36: pinesh.mehta@bgf.co.uk | I36: https://www.linkedin.com/in/pinesh-mehta-29448a14/ | N36: Foreign PE with potfolio companies not having Indian offices
A37: Transom Capital | B37: USA | C37: 46035 | D37: 46091 | E37: https://transomcap.com/ | F37: Steve Kim | G37: Managing Director | H37: skim@transomcap.com | I37: https://www.linkedin.com/in/steve-kim-4194b29/ | N37: Foreign PE with potfolio companies not having Indian offices
A38: Runtide Capital | B38: USA | C38: 46035 | D38: Got response | E38: https://www.runtidecapital.com/ | F38: Robert Manning | G38: Managing Partner | H38: rmanning@runtidecapital.com | I38: https://www.linkedin.com/in/robert-manning-268203/ | N38: Foreign PE with potfolio companies not having Indian offices
A39: Great Hill Partners | B39: USA | C39: 46035 | D39: 46091 | E39: https://www.greathillpartners.com/ | F39: Atle Skalleberg | G39: Growth Partner | H39: askalleberg@greathillpartners.com | I39: https://www.linkedin.com/in/skalleberg/ | N39: Foreign PE with potfolio companies not having Indian offices
A40: Petros Partners | B40: USA | C40: 46035 | D40: 46091 | E40: https://www.petrospartners.com/ | F40: Mansoor Ghori | G40: Board Mamber/Co-Founder/Vice Chairman | H40: mansoor@petrospartners.com | I40: https://www.linkedin.com/in/mansoor-ghori-14474/ | N40: Foreign PE with potfolio companies not having Indian offices
A41: Arlington Capital Partners | B41: USA | C41: 46035 | D41: Got response | E41: https://arlingtoncap.com/ | F41: Ben Ramundo | G41: Managing Director | H41: bramundo@arlingtoncap.com | I41: https://www.linkedin.com/in/benjaminramundo89/ | N41: Foreign PE with potfolio companies not having Indian offices
A42: La Maison Partners | B42: France | C42: 46058 | D42: Got response | E42: https://www.lamaisonpartners.fr/en/ | F42: Long Zhou | G42: Investment Director | H42: l.zhou@lamaisonpartners.fr | I42: https://www.linkedin.com/in/long-zhou-44babb3b/ | N42: Foreign PE with potfolio companies not having Indian offices
...

Sheet PE porfolio names final
A1: PE porfotio buyers - 22by7
A2: Exchange rate as on date | B2: 90.26
A3: Revenue and headcount data taken from Inven unless specified
A4: =COUNTA(A8:A1048576) -> 60
A7: Company Name | B7: HQ | C7: Initial email | D7: Status | E7: Rationale | F7: Revenue from source | G7: Rev (INR Cr) | H7: Headcount | I7: Website link | J7: Contact Name 1 | K7: Designation 1 | L7: Email Id 1 | M7: Linkedin 1 | N7: Contact Name 2 | O7: Designation 2 | P7: Email Id 2 | Q7: Linkedin 2 | R7: Holding company | S7: Holding company website link | T7: Bucket
A8: Celebal Technologies | B8: India | C8: 46056 | D8: 46112 | E8: Similar services; Indian locations | F8: 2811 | G8: =F8/10 -> 281.1 | H8: 2893 | I8: https://celebaltech.com/ | J8: Anirudh Kala | K8: CEO | L8: anirudh@celebaltech.com | M8: https://www.linkedin.com/in/anirudhkala/ | R8: Norwest | S8: https://www.norwest.com/ | T8: Expand Indian presence
A9: NxtGen | B9: India | C9: 46062 | D9: Got response | E9: Similar services; Indian locations | F9: 2349 | G9: =F9/10 -> 234.9 | H9: 492 | I9: https://nxtgen.com/ | J9: Rajgopal A S | K9: CEO/Managing Director | L9: raj@nxtgen.com | M9: https://www.linkedin.com/in/rajgopal-as/ | R9: Intel Capital | S9: https://www.intelcapital.com/ | T9: Expand Indian presence
A10: Accion Labs | B10: USA | C10: 46062 | D10: Vishnu got response | E10: Similar services; Indian locations | F10: 273 | G10: =(F10*1000000*$B$2)/10000000 -> 2464.098 | H10: 2381 | I10: https://www.accionlabs.com/ | J10: Kinesh Doshi | K10: CEO/Co-Founder | L10: kinesh.doshi@accionlabs.com | M10: https://www.linkedin.com/in/kinesh-doshi/ | R10: Trunorth | S10: https://www.truenorth.co.in/ | T10: Expand Indian presence
A11: MorganFranklin Cyber | B11: USA | C11: 46062 | D11: 46120 | E11: Similar services; Indian locations | F11: 200 | G11: =(F11*1000000*$B$2)/10000000 -> 1805.2 | H11: 137 | I11: https://mfcyber.com/ | J11: Peter Schile | K11: Co-Founder/President | L11: pete.schile@morganfranklin.com | M11: https://www.linkedin.com/in/peterschile/ | R11: MC Partners | S11: https://www.mcpartners.com/ | T11: Expand Indian presence
A12: Armor Defense | B12: USA | C12: 46062 | D12: 46120 | E12: Similar services; Indian locations | F12: 21 | G12: =(F12*1000000*$B$2)/10000000 -> 189.546 | H12: 28 | I12: https://www.armor.com/ | J12: Ananya Amin | K12: Managing Director | L12: ananya.amin@armor.com | M12: https://www.linkedin.com/in/ananyaamin/ | R12: The Stephens Group | S12: https://www.stephensgroup.com/ | T12: Expand Indian presence
A13: Centroid Systems | B13: USA | C13: 46062 | D13: 46120 | E13: Similar services; Indian locations | F13: 57 | G13: =(F13*1000000*$B$2)/10000000 -> 514.482 | H13: 253 | I13: https://www.centroid.com/ | J13: Ken Bowles | K13: CFO | L13: ken.bowles@centroid.com | M13: https://www.linkedin.com/in/kenbowles/ | R13: VSS Capital Partners | S13: https://www.vss.com/ | T13: Expand Indian presence
A14: Blue Mantis | B14: USA | C14: 46062 | D14: 46120 | E14: Similar services; Indian locations | F14: 37 | G14: =(F14*1000000*$B$2)/10000000 -> 333.962 | H14: 514 | I14: https://www.bluemantis.com/ | J14: Jason Bernstein | K14: CFO | L14: jason.bernstein@bluemantis.com | M14: https://www.linkedin.com/in/jason-bernstein-71b8136/ | R14: Abry Partners | S14: https://abry.com/ | T14: Expand Indian presence
A15: Buchanan Technologies | B15: USA | C15: 46062 | D15: 46120 | E15: Similar services; Indian locations | F15: 75 | G15: =(F15*1000000*$B$2)/10000000 -> 676.95 | H15: 786 | I15: https://www.buchanan.com/ | J15: Manish Yadav | K15: Senior Vice President | L15: myadav@buchanan.com | M15: https://www.linkedin.com/in/manish-yadav-736580143/ | R15: Lightview Partners | S15: https://www.lightviewcapital.com/ | T15: Expand Indian presence
A16: SDG Corporation | B16: USA | C16: 46062 | D16: 46120 | E16: Similar services; Indian locations | F16: 56 | G16: =(F16*1000000*$B$2)/10000000 -> 505.456 | H16: 693 | I16: https://sdgc.com/ | J16: Ajay Gupta | K16: CEO | L16: ajay@sdgc.com | M16: https://www.linkedin.com/in/ajay-gupta-016846/ | R16: Recognize | S16: https://recognize.com/ | T16: Expand Indian presence
A17: Thrive | B17: USA | C17: 46062 | D17: Got response | E17: Similar services; APAC locations | F17: 400 | G17: =(F17*1000000*$B$2)/10000000 -> 3610.4 | H17: 1936 | I17: https://thrivenextgen.com/ | J17: Bill McLaughlin | K17: Board Member/CEO | L17: bmclaughlin@thrivenetworks.com | M17: https://www.linkedin.com/in/billmclaughlinmsp/ | R17: MC Partners | S17: https://www.mcpartners.com/ | T17: Expand Asian presence
A18: Nuspire | B18: USA | C18: 46064 | D18: 46120 | E18: Similar services | F18: 237 | G18: =(F18*1000000*$B$2)/10000000 -> 2139.162 | H18: 2429 | I18: https://security.pditechnologies.com/ | J18: Dan Hoban | K18: Executive Vice President | L18: dan.hoban@nuspire.com | M18: https://www.linkedin.com/in/danhoban/ | R18: Insight Partners | S18: https://www.insightpartners.com/ | T18: Offshore/onshore expansion
A19: Redhelm | B19: USA | C19: 46064 | D19: 46120 | E19: Similar services | F19: 250 | G19: =(F19*1000000*$B$2)/10000000 -> 2256.5 | H19: 344 | I19: https://redhelm.com/ | J19: James Wilson | K19: CEO | L19: jwilson@redhelm.com | M19: https://www.linkedin.com/in/james-arthur-wilson/ | R19: Frontenac | S19: https://frontenac.com/ | T19: Offshore/onshore expansion
A20: Integris | B20: USA | C20: 46064 | D20: Vishnu reached out | E20: Similar services | F20: 73 | G20: =(F20*1000000*$B$2)/10000000 -> 658.898 | H20: 1181 | I20: https://integrisit.com/ | J20: Glenn Mathis | K20: Board Member/CEO | L20: glenn.mathis@integrisit.com | M20: https://www.linkedin.com/in/glennmathis/ | R20: Frontenac | S20: https://frontenac.com/ | T20: Offshore/onshore expansion
A21: Ntiva | B21: USA | C21: 46064 | D21: Got response | E21: Similar services | F21: 58 | G21: =(F21*1000000*$B$2)/10000000 -> 523.508 | H21: 477 | I21: https://www.ntiva.com/ | J21: Kevin Cook | K21: CSO | L21: kevin.cook@ntiva.com | M21: https://www.linkedin.com/in/kevin-cook-ntiva/ | R21: PSP Partners | S21: https://www.psppartners.com/ | T21: Offshore/onshore expansion
A22: Magna5 | B22: USA | C22: 46064 | D22: Got response | E22: Similar services | F22: 31 | G22: =(F22*1000000*$B$2)/10000000 -> 279.806 | H22: 335 | I22: https://www.magna5.com/ | J22: Robert Farina | K22: CEO | L22: robert.farina@magna5.com | M22: https://www.linkedin.com/in/robert-farina-33065914/ | R22: Newspring Holdings | S22: https://newspringcapital.com/ | T22: Offshore/onshore expansion
A23: Abacus Group LLC | B23: USA | C23: 46064 | D23: Got response | E23: Similar services | F23: 66 | G23: =(F23*1000000*$B$2)/10000000 -> 595.716 | H23: 446 | I23: https://www.abacusgroupllc.com/ | J23: Anthony J. D'Ambrosia | K23: Board Member/CEO | L23: ajd@abacusgroupllc.com | M23: https://www.linkedin.com/in/anthonyjdambrosi/ | R23: FFL Group | S23: https://fflpartners.com/ | T23: Offshore/onshore expansion
A24: Compass MSP | B24: USA | C24: 46064 | D24: Got response from PE | E24: Similar services | F24: 28 | G24: =(F24*1000000*$B$2)/10000000 -> 252.728 | H24: 240 | I24: https://compassmsp.com/ | J24: Michael Rapp | K24: CEO | L24: mrapp@compassmsp.com | M24: https://www.linkedin.com/in/michaelrapp22/ | R24: Agellus Capital | S24: https://www.agellus.com/ | T24: Offshore/onshore expansion
A25: Meriplex | B25: USA | C25: 46064 | D25: 46120 | E25: Similar services | F25: 66 | G25: =(F25*1000000*$B$2)/10000000 -> 595.716 | H25: 578 | I25: https://meriplex.com/ | J25: Garrett Else | K25: CFO | L25: garrett.else@meriplex.com | M25: https://www.linkedin.com/in/garrettelse/ | R25: Virtuvian Partners | S25: https://www.vitruvianpartners.com/ | T25: Offshore/onshore expansion
A26: Ascend Technologies | B26: USA | C26: 46064 | D26: 46120 | E26: Similar services | F26: 35 | G26: =(F26*1000000*$B$2)/10000000 -> 315.91 | H26: 303 | I26: https://teamascend.com/ | J26: Amar K. Patel | K26: CEO | L26: apatel@teamascend.com | M26: https://www.linkedin.com/in/amar311/ | R26: MC Partners | S26: https://www.mcpartners.com/ | T26: Offshore/onshore expansion
A27: C3 Integrated Solutions | B27: USA | C27: 46064 | D27: 46120 | E27: Similar services | F27: 11 | G27: =(F27*1000000*$B$2)/10000000 -> 99.286 | H27: 123 | I27: https://c3isit.com/ | J27: Marc Pantoni | K27: CEO | L27: mpantoni@c3isit.com | M27: https://www.linkedin.com/in/marc-pantoni-99961363/ | R27: MC Partners | S27: https://www.mcpartners.com/ | T27: Offshore/onshore expansion
A28: Consortium | B28: USA | C28: 46064 | D28: 46120 | E28: Similar services | F28: 11 | G28: =(F28*1000000*$B$2)/10000000 -> 99.286 | H28: 78 | I28: https://consortium.net/ | J28: Nate Ungerott | K28: CEO | L28: nate.ungerott@consortium.net | M28: https://www.linkedin.com/in/nateungerott/ | R28: MC Partners | S28: https://www.mcpartners.com/ | T28: Offshore/onshore expansion
A29: Iron Bow Technologies | B29: USA | C29: 46064 | D29: 46120 | E29: Similar services | F29: 51 | G29: =(F29*1000000*$B$2)/10000000 -> 460.326 | H29: 922 | I29: https://ironbow.com/ | J29: Rene LaVigne | K29: CEO/President | L29: rene.lavigne@ironbow.com | M29: https://www.linkedin.com/in/rene-lavigne/ | R29: HIG Capital | S29: https://hig.com/ | T29: Offshore/onshore expansion
A30: Trace3 | B30: USA | C30: 46064 | D30: 46120 | E30: Similar services | F30: 226 | G30: =(F30*1000000*$B$2)/10000000 -> 2039.876 | H30: 1416 | I30: https://www.trace3.com/ | J30: Joe Quaglia | K30: CEO | L30: joe.quaglia@trace3.com | M30: https://www.linkedin.com/in/joequaglia/ | R30: HIG Capital | S30: https://hig.com/ | T30: Offshore/onshore expansion
A31: 360 Advanced | B31: USA | C31: 46064 | D31: Got response | E31: Similar services | F31: 11 | G31: =(F31*1000000*$B$2)/10000000 -> 99.286 | H31: 131 | I31: https://360advanced.com/ | J31: Gregory Bosl | K31: CFO | L31: gbosl@360advanced.com | M31: https://www.linkedin.com/in/gregorybosl/ | R31: Bregal Sagemount | S31: https://www.sagemount.com/ | T31: Offshore/onshore expansion
A32: CyberOne Security | B32: USA | C32: 46064 | D32: Got response | E32: Similar services | F32: 10 | G32: =(F32*1000000*$B$2)/10000000 -> 90.26 | H32: 77 | I32: https://cyberonesecurity.com/ | J32: Tera Davis | K32: CEO | L32: tera@cyberonesecurity.com | M32: https://www.linkedin.com/in/tera-davis-42aa0a1/ | R32: Bregal Sagemount | S32: https://www.sagemount.com/ | T32: Offshore/onshore expansion
A33: Corsica Technologies | B33: USA | C33: 46064 | D33: Bounced | E33: Similar services | F33: 9 | G33: =(F33*1000000*$B$2)/10000000 -> 81.234 | H33: 120 | I33: https://corsicatech.com/ | J33: Jennifer Lynn Parmenter | K33: CEO | L33: jparmenter@corsicatech.com | M33: https://www.linkedin.com/in/jennifer-lynn-parmenter-cma-52a75b13/ | R33: Iverness Graham | S33: https://www.invernessgraham.com/ | T33: Offshore/onshore expansion
A34: Entech | B34: USA | C34: 46064 | D34: 46120 | E34: Similar services | F34: 11 | G34: =(F34*1000000*$B$2)/10000000 -> 99.286 | H34: 72 | I34: https://www.entechus.com/ | J34: Buddy Martin | K34: CEO | L34: buddy@entechus.com | M34: https://www.linkedin.com/in/buddymartin/ | R34: Prospect Partners | S34: https://prospect-partners.com/ | T34: Offshore/onshore expansion
A35: Netrio | B35: USA | C35: 46064 | D35: Got response | E35: Similar services | F35: 100 | G35: =(F35*1000000*$B$2)/10000000 -> 902.6 | H35: 264 | I35: https://www.netrio.com/ | J35: Mark Clayman | K35: CEO | L35: mark.clayman@netrio.com | M35: https://www.linkedin.com/in/mark-clayman-70b55/ | R35: L Squared Capital | S35: https://www.lsquaredcap.com/ | T35: Offshore/onshore expansion
A36: Novatech | B36: USA | C36: 46064 | D36: Vishnu reached out | E36: Similar services | F36: 72 | G36: =(F36*1000000*$B$2)/10000000 -> 649.872 | H36: 721 | I36: https://novatech.net/ | J36: Jeff Hoctor | K36: CFO | L36: jhoctor@novatech.net | M36: https://www.linkedin.com/in/jeff-hoctor-cpa-b8b17a3/ | R36: Perpetual Capital Partners | S36: https://perpetualcapitalpartners.com/ | T36: Offshore/onshore expansion
A37: New Charter Technolgies | B37: USA | C37: 46064 | D37: 46120 | E37: Similar services | F37: 46 | G37: =(F37*1000000*$B$2)/10000000 -> 415.196 | H37: 75 | I37: https://www.newchartertech.com/ | J37: Peter Melby | K37: CEO | L37: peter@newchartertech.com | M37: https://www.linkedin.com/in/petermelby/ | R37: Oval Partners | S37: https://www.ovalpartners.com/ | T37: Offshore/onshore expansion
A38: CyberGuard Advantage | B38: USA | C38: 46064 | D38: Got response | E38: Similar services | F38: 9.2 | G38: =(F38*1000000*$B$2)/10000000 -> 83.0392 | H38: 52 | I38: https://www.cgcompliance.com/ | J38: Jim Jimenez | K38: Managing Partner | L38: jim.jimenez@cgcompliance.com | M38: https://www.linkedin.com/in/jim-jimenez-cpa-4b7a1ab/ | R38: Atlantic Street Capital | S38: https://www.atlanticstreetcapital.com/ | T38: Offshore/onshore expansion
A39: CyberlinkASP | B39: USA | C39: 46064 | D39: 46120 | E39: Similar services | F39: 11 | G39: =(F39*1000000*$B$2)/10000000 -> 99.286 | H39: 58 | I39: https://cyberlinkasp.com/ | J39: Kevin McGahey | K39: CFO | L39: kevin.mcgahey@cybasp.com | M39: https://www.linkedin.com/in/kevinmcgahey/ | R39: Seaport Capital | S39: https://www.seaportcapital.com/ | T39: Offshore/onshore expansion
A40: Coretelligent | B40: USA | C40: 46064 | D40: 46120 | E40: Similar services | F40: 29 | G40: =(F40*1000000*$B$2)/10000000 -> 261.754 | H40: 241 | I40: https://www.coretelligent.com/ | J40: Vijay Iyer | K40: CEO | L40: viyer@core.tech | M40: https://www.linkedin.com/in/vijay1balasubramanian/ | R40: Northwest Equity Partners | S40: https://nep.com/ | T40: Offshore/onshore expansion
A41: Dataprise | B41: USA | C41: 46064 | D41: 46120 | E41: Similar services | F41: N/A | G41: N/A | H41: 572 | I41: https://www.dataprise.com/ | J41: Siobhan de Leeuw | K41: CFO | L41: siobhan.deleeuw@dataprise.com | M41: https://www.linkedin.com/in/siobhan-de-leeuw-97234a4/ | R41: Trinity Hunt Partners | S41: https://www.trinityhunt.com/ | T41: Offshore/onshore expansion
A42: Five Nines | B42: USA | C42: 46064 | D42: 46120 | E42: Similar services | F42: 14 | G42: =(F42*1000000*$B$2)/10000000 -> 126.364 | H42: 158 | I42: https://fivenines.com/ | J42: Joel Friesen | K42: CEO | L42: joel@gonines.com | M42: https://www.linkedin.com/in/joel-friesen-9199a7a/ | R42: SNH Capital Partners | S42: https://www.snhcapitalpartners.com/ | T42: Offshore/onshore expansion
...

Sheet Emailing schedule
A1: Next set of emails due in (days) | C1: =MIN(J7:M1048576) -> 0 | D1: Count | E1: =SUBTOTAL(3,A7:A1048576) -> 130
D2: Check | E2: =E1-'PE names final'!A2-'PE porfolio names final'!A4 -> 0
B5: =IF(COUNTIF(B7:B1048576,"Error")>0,"Error", "Go") -> Go | C5: =IF(COUNTIF(C7:C1048576,"Error")>0,"Error", "Go") -> Go | E5: =IF(COUNTIF(E7:E1048576,"Error")>0,"Error", "Go") -> Go
A6: Company name | B6: Check to previous page | C6: Regarding | D6: Initial date | E6: Status | F6: Bi-weekly follow up | G6: Bi-weekly follow up | H6: Bi-weekly follow up | I6: Bi-weekly follow up | J6: Follow ups (in days)
A7: Trunorth | B7: =IF(COUNTIF('PE names final'!A:A, A7)+COUNTIF('PE porfolio names final'!A:A,A7)=1, "Yes", "Error") -> Yes | C7: {=_xlfn.IFS(AND(COUNTIF('PE names final'!A:A,A7)>0,COUNTIF('PE porfolio names final'!A:A,A7)>0),"Error",COUNTIF('PE names final'!A:A,A7)>0,"PE",COUNTIF('PE porfolio names final'!A:A,A7)>0,"Portfolio",TRUE,"")} -> PE | D7: =_xlfn.LET(_xlpm.L,IFERROR(_xlfn.XLOOKUP(A7,'PE names final'!A:A,'PE names final'!C:C),_xlfn.XLOOKUP(A7,'PE porfolio names final'!A:A,'PE porfolio names final'!C:C,"")),IF(_xlpm.L=0,"",_xlpm.L)) -> 46034 | E7: =_xlfn.LET(_xlpm.d,IFERROR(_xlfn.XLOOKUP(A7,'PE names final'!A:A,'PE names final'!D:D),_xlfn.XLOOKUP(A7,'PE porfolio names final'!A:A,'PE porfolio names final'!D:D,"")),IF(_xlpm.d=0,"",IF(_xlpm.d<D7,"Error",_xlpm.d))) -> 46091 | F7: =IF(ISNUMBER($E7),D7+14,"") -> 46048 | G7: =IF(ISNUMBER($E7),F7+14,"") -> 46062 | H7: =IF(ISNUMBER($E7),G7+14,"") -> 46076 | I7: =IF(ISNUMBER($E7),H7+14,"") -> 46090 | J7: =IF(NOT(ISNUMBER($E7)),"",IF($E7>=F7,"Done",F7-TODAY())) -> Done | K7: =IF(NOT(ISNUMBER($E7)),"",IF($E7>=G7,"Done",G7-TODAY())) -> Done | L7: =IF(NOT(ISNUMBER($E7)),"",IF($E7>=H7,"Done",H7-TODAY())) -> Done | M7: =IF(NOT(ISNUMBER($E7)),"",IF($E7>=I7,"Done",I7-TODAY())) -> Done
A8: MC Partners | B8: =IF(COUNTIF('PE names final'!A:A, A8)+COUNTIF('PE porfolio names final'!A:A,A8)=1, "Yes", "Error") -> Yes | C8: {=_xlfn.IFS(AND(COUNTIF('PE names final'!A:A,A8)>0,COUNTIF('PE porfolio names final'!A:A,A8)>0),"PE & Portfolio",COUNTIF('PE names final'!A:A,A8)>0,"PE",COUNTIF('PE porfolio names final'!A:A,A8)>0,"Portfolio",TRUE,"")} -> PE | D8: =_xlfn.LET(_xlpm.L,IFERROR(_xlfn.XLOOKUP(A8,'PE names final'!A:A,'PE names final'!C:C),_xlfn.XLOOKUP(A8,'PE porfolio names final'!A:A,'PE porfolio names final'!C:C,"")),IF(_xlpm.L=0,"",_xlpm.L)) -> 46055 | E8: =_xlfn.LET(_xlpm.d,IFERROR(_xlfn.XLOOKUP(A8,'PE names final'!A:A,'PE names final'!D:D),_xlfn.XLOOKUP(A8,'PE porfolio names final'!A:A,'PE porfolio names final'!D:D,"")),IF(_xlpm.d=0,"",IF(_xlpm.d<D8,"Error",_xlpm.d))) -> Got response | F8: =IF(ISNUMBER($E8),D8+14,"") | G8: =IF(ISNUMBER($E8),F8+14,"") | H8: =IF(ISNUMBER($E8),G8+14,"") | I8: =IF(ISNUMBER($E8),H8+14,"") | J8: =IF(NOT(ISNUMBER($E8)),"",IF($E8>=F8,"Done",F8-TODAY())) | K8: =IF(NOT(ISNUMBER($E8)),"",IF($E8>=G8,"Done",G8-TODAY())) | L8: =IF(NOT(ISNUMBER($E8)),"",IF($E8>=H8,"Done",H8-TODAY())) | M8: =IF(NOT(ISNUMBER($E8)),"",IF($E8>=I8,"Done",I8-TODAY()))
A9: Norwest | B9: =IF(COUNTIF('PE names final'!A:A, A9)+COUNTIF('PE porfolio names final'!A:A,A9)=1, "Yes", "Error") -> Yes | C9: {=_xlfn.IFS(AND(COUNTIF('PE names final'!A:A,A9)>0,COUNTIF('PE porfolio names final'!A:A,A9)>0),"PE & Portfolio",COUNTIF('PE names final'!A:A,A9)>0,"PE",COUNTIF('PE porfolio names final'!A:A,A9)>0,"Portfolio",TRUE,"")} -> PE | D9: =_xlfn.LET(_xlpm.L,IFERROR(_xlfn.XLOOKUP(A9,'PE names final'!A:A,'PE names final'!C:C),_xlfn.XLOOKUP(A9,'PE porfolio names final'!A:A,'PE porfolio names final'!C:C,"")),IF(_xlpm.L=0,"",_xlpm.L)) -> 46051 | E9: =_xlfn.LET(_xlpm.d,IFERROR(_xlfn.XLOOKUP(A9,'PE names final'!A:A,'PE names final'!D:D),_xlfn.XLOOKUP(A9,'PE porfolio names final'!A:A,'PE porfolio names final'!D:D,"")),IF(_xlpm.d=0,"",IF(_xlpm.d<D9,"Error",_xlpm.d))) -> 46107 | F9: =IF(ISNUMBER($E9),D9+14,"") -> 46065 | G9: =IF(ISNUMBER($E9),F9+14,"") -> 46079 | H9: =IF(ISNUMBER($E9),G9+14,"") -> 46093 | I9: =IF(ISNUMBER($E9),H9+14,"") -> 46107 | J9: =IF(NOT(ISNUMBER($E9)),"",IF($E9>=F9,"Done",F9-TODAY())) -> Done | K9: =IF(NOT(ISNUMBER($E9)),"",IF($E9>=G9,"Done",G9-TODAY())) -> Done | L9: =IF(NOT(ISNUMBER($E9)),"",IF($E9>=H9,"Done",H9-TODAY())) -> Done | M9: =IF(NOT(ISNUMBER($E9)),"",IF($E9>=I9,"Done",I9-TODAY())) -> Done
A10: Intel Capital | B10: =IF(COUNTIF('PE names final'!A:A, A10)+COUNTIF('PE porfolio names final'!A:A,A10)=1, "Yes", "Error") -> Yes | C10: {=_xlfn.IFS(AND(COUNTIF('PE names final'!A:A,A10)>0,COUNTIF('PE porfolio names final'!A:A,A10)>0),"PE & Portfolio",COUNTIF('PE names final'!A:A,A10)>0,"PE",COUNTIF('PE porfolio names final'!A:A,A10)>0,"Portfolio",TRUE,"")} -> PE | D10: =_xlfn.LET(_xlpm.L,IFERROR(_xlfn.XLOOKUP(A10,'PE names final'!A:A,'PE names final'!C:C),_xlfn.XLOOKUP(A10,'PE porfolio names final'!A:A,'PE porfolio names final'!C:C,"")),IF(_xlpm.L=0,"",_xlpm.L)) -> 46051 | E10: =_xlfn.LET(_xlpm.d,IFERROR(_xlfn.XLOOKUP(A10,'PE names final'!A:A,'PE names final'!D:D),_xlfn.XLOOKUP(A10,'PE porfolio names final'!A:A,'PE porfolio names final'!D:D,"")),IF(_xlpm.d=0,"",IF(_xlpm.d<D10,"Error",_xlpm.d))) -> 46107 | F10: =IF(ISNUMBER($E10),D10+14,"") -> 46065 | G10: =IF(ISNUMBER($E10),F10+14,"") -> 46079 | H10: =IF(ISNUMBER($E10),G10+14,"") -> 46093 | I10: =IF(ISNUMBER($E10),H10+14,"") -> 46107 | J10: =IF(NOT(ISNUMBER($E10)),"",IF($E10>=F10,"Done",F10-TODAY())) -> Done | K10: =IF(NOT(ISNUMBER($E10)),"",IF($E10>=G10,"Done",G10-TODAY())) -> Done | L10: =IF(NOT(ISNUMBER($E10)),"",IF($E10>=H10,"Done",H10-TODAY())) -> Done | M10: =IF(NOT(ISNUMBER($E10)),"",IF($E10>=I10,"Done",I10-TODAY())) -> Done
A11: The Stephens Group | B11: =IF(COUNTIF('PE names final'!A:A, A11)+COUNTIF('PE porfolio names final'!A:A,A11)=1, "Yes", "Error") -> Yes | C11: {=_xlfn.IFS(AND(COUNTIF('PE names final'!A:A,A11)>0,COUNTIF('PE porfolio names final'!A:A,A11)>0),"PE & Portfolio",COUNTIF('PE names final'!A:A,A11)>0,"PE",COUNTIF('PE porfolio names final'!A:A,A11)>0,"Portfolio",TRUE,"")} -> PE | D11: =_xlfn.LET(_xlpm.L,IFERROR(_xlfn.XLOOKUP(A11,'PE names final'!A:A,'PE names final'!C:C),_xlfn.XLOOKUP(A11,'PE porfolio names final'!A:A,'PE porfolio names final'!C:C,"")),IF(_xlpm.L=0,"",_xlpm.L)) -> 46043 | E11: =_xlfn.LET(_xlpm.d,IFERROR(_xlfn.XLOOKUP(A11,'PE names final'!A:A,'PE names final'!D:D),_xlfn.XLOOKUP(A11,'PE porfolio names final'!A:A,'PE porfolio names final'!D:D,"")),IF(_xlpm.d=0,"",IF(_xlpm.d<D11,"Error",_xlpm.d))) -> 46099 | F11: =IF(ISNUMBER($E11),D11+14,"") -> 46057 | G11: =IF(ISNUMBER($E11),F11+14,"") -> 46071 | H11: =IF(ISNUMBER($E11),G11+14,"") -> 46085 | I11: =IF(ISNUMBER($E11),H11+14,"") -> 46099 | J11: =IF(NOT(ISNUMBER($E11)),"",IF($E11>=F11,"Done",F11-TODAY())) -> Done | K11: =IF(NOT(ISNUMBER($E11)),"",IF($E11>=G11,"Done",G11-TODAY())) -> Done | L11: =IF(NOT(ISNUMBER($E11)),"",IF($E11>=H11,"Done",H11-TODAY())) -> Done | M11: =IF(NOT(ISNUMBER($E11)),"",IF($E11>=I11,"Done",I11-TODAY())) -> Done
A12: VSS Capital Partners | B12: =IF(COUNTIF('PE names final'!A:A, A12)+COUNTIF('PE porfolio names final'!A:A,A12)=1, "Yes", "Error") -> Yes | C12: {=_xlfn.IFS(AND(COUNTIF('PE names final'!A:A,A12)>0,COUNTIF('PE porfolio names final'!A:A,A12)>0),"PE & Portfolio",COUNTIF('PE names final'!A:A,A12)>0,"PE",COUNTIF('PE porfolio names final'!A:A,A12)>0,"Portfolio",TRUE,"")} -> PE | D12: =_xlfn.LET(_xlpm.L,IFERROR(_xlfn.XLOOKUP(A12,'PE names final'!A:A,'PE names final'!C:C),_xlfn.XLOOKUP(A12,'PE porfolio names final'!A:A,'PE porfolio names final'!C:C,"")),IF(_xlpm.L=0,"",_xlpm.L)) -> 46062 | E12: =_xlfn.LET(_xlpm.d,IFERROR(_xlfn.XLOOKUP(A12,'PE names final'!A:A,'PE names final'!D:D),_xlfn.XLOOKUP(A12,'PE porfolio names final'!A:A,'PE porfolio names final'!D:D,"")),IF(_xlpm.d=0,"",IF(_xlpm.d<D12,"Error",_xlpm.d))) -> 46120 | F12: =IF(ISNUMBER($E12),D12+14,"") -> 46076 | G12: =IF(ISNUMBER($E12),F12+14,"") -> 46090 | H12: =IF(ISNUMBER($E12),G12+14,"") -> 46104 | I12: =IF(ISNUMBER($E12),H12+14,"") -> 46118 | J12: =IF(NOT(ISNUMBER($E12)),"",IF($E12>=F12,"Done",F12-TODAY())) -> Done | K12: =IF(NOT(ISNUMBER($E12)),"",IF($E12>=G12,"Done",G12-TODAY())) -> Done | L12: =IF(NOT(ISNUMBER($E12)),"",IF($E12>=H12,"Done",H12-TODAY())) -> Done | M12: =IF(NOT(ISNUMBER($E12)),"",IF($E12>=I12,"Done",I12-TODAY())) -> Done
A13: Abry Partners | B13: =IF(COUNTIF('PE names final'!A:A, A13)+COUNTIF('PE porfolio names final'!A:A,A13)=1, "Yes", "Error") -> Yes | C13: {=_xlfn.IFS(AND(COUNTIF('PE names final'!A:A,A13)>0,COUNTIF('PE porfolio names final'!A:A,A13)>0),"PE & Portfolio",COUNTIF('PE names final'!A:A,A13)>0,"PE",COUNTIF('PE porfolio names final'!A:A,A13)>0,"Portfolio",TRUE,"")} -> PE | D13: =_xlfn.LET(_xlpm.L,IFERROR(_xlfn.XLOOKUP(A13,'PE names final'!A:A,'PE names final'!C:C),_xlfn.XLOOKUP(A13,'PE porfolio names final'!A:A,'PE porfolio names final'!C:C,"")),IF(_xlpm.L=0,"",_xlpm.L)) -> 46051 | E13: =_xlfn.LET(_xlpm.d,IFERROR(_xlfn.XLOOKUP(A13,'PE names final'!A:A,'PE names final'!D:D),_xlfn.XLOOKUP(A13,'PE porfolio names final'!A:A,'PE porfolio names final'!D:D,"")),IF(_xlpm.d=0,"",IF(_xlpm.d<D13,"Error",_xlpm.d))) -> 46107 | F13: =IF(ISNUMBER($E13),D13+14,"") -> 46065 | G13: =IF(ISNUMBER($E13),F13+14,"") -> 46079 | H13: =IF(ISNUMBER($E13),G13+14,"") -> 46093 | I13: =IF(ISNUMBER($E13),H13+14,"") -> 46107 | J13: =IF(NOT(ISNUMBER($E13)),"",IF($E13>=F13,"Done",F13-TODAY())) -> Done | K13: =IF(NOT(ISNUMBER($E13)),"",IF($E13>=G13,"Done",G13-TODAY())) -> Done | L13: =IF(NOT(ISNUMBER($E13)),"",IF($E13>=H13,"Done",H13-TODAY())) -> Done | M13: =IF(NOT(ISNUMBER($E13)),"",IF($E13>=I13,"Done",I13-TODAY())) -> Done
A14: Lightview Partners | B14: =IF(COUNTIF('PE names final'!A:A, A14)+COUNTIF('PE porfolio names final'!A:A,A14)=1, "Yes", "Error") -> Yes | C14: {=_xlfn.IFS(AND(COUNTIF('PE names final'!A:A,A14)>0,COUNTIF('PE porfolio names final'!A:A,A14)>0),"PE & Portfolio",COUNTIF('PE names final'!A:A,A14)>0,"PE",COUNTIF('PE porfolio names final'!A:A,A14)>0,"Portfolio",TRUE,"")} -> PE | D14: =_xlfn.LET(_xlpm.L,IFERROR(_xlfn.XLOOKUP(A14,'PE names final'!A:A,'PE names final'!C:C),_xlfn.XLOOKUP(A14,'PE porfolio names final'!A:A,'PE porfolio names final'!C:C,"")),IF(_xlpm.L=0,"",_xlpm.L)) -> 46062 | E14: =_xlfn.LET(_xlpm.d,IFERROR(_xlfn.XLOOKUP(A14,'PE names final'!A:A,'PE names final'!D:D),_xlfn.XLOOKUP(A14,'PE porfolio names final'!A:A,'PE porfolio names final'!D:D,"")),IF(_xlpm.d=0,"",IF(_xlpm.d<D14,"Error",_xlpm.d))) -> 46120 | F14: =IF(ISNUMBER($E14),D14+14,"") -> 46076 | G14: =IF(ISNUMBER($E14),F14+14,"") -> 46090 | H14: =IF(ISNUMBER($E14),G14+14,"") -> 46104 | I14: =IF(ISNUMBER($E14),H14+14,"") -> 46118 | J14: =IF(NOT(ISNUMBER($E14)),"",IF($E14>=F14,"Done",F14-TODAY())) -> Done | K14: =IF(NOT(ISNUMBER($E14)),"",IF($E14>=G14,"Done",G14-TODAY())) -> Done | L14: =IF(NOT(ISNUMBER($E14)),"",IF($E14>=H14,"Done",H14-TODAY())) -> Done | M14: =IF(NOT(ISNUMBER($E14)),"",IF($E14>=I14,"Done",I14-TODAY())) -> Done
A15: Recognize | B15: =IF(COUNTIF('PE names final'!A:A, A15)+COUNTIF('PE porfolio names final'!A:A,A15)=1, "Yes", "Error") -> Yes | C15: {=_xlfn.IFS(AND(COUNTIF('PE names final'!A:A,A15)>0,COUNTIF('PE porfolio names final'!A:A,A15)>0),"PE & Portfolio",COUNTIF('PE names final'!A:A,A15)>0,"PE",COUNTIF('PE porfolio names final'!A:A,A15)>0,"Portfolio",TRUE,"")} -> PE | D15: =_xlfn.LET(_xlpm.L,IFERROR(_xlfn.XLOOKUP(A15,'PE names final'!A:A,'PE names final'!C:C),_xlfn.XLOOKUP(A15,'PE porfolio names final'!A:A,'PE porfolio names final'!C:C,"")),IF(_xlpm.L=0,"",_xlpm.L)) -> 46062 | E15: =_xlfn.LET(_xlpm.d,IFERROR(_xlfn.XLOOKUP(A15,'PE names final'!A:A,'PE names final'!D:D),_xlfn.XLOOKUP(A15,'PE porfolio names final'!A:A,'PE porfolio names final'!D:D,"")),IF(_xlpm.d=0,"",IF(_xlpm.d<D15,"Error",_xlpm.d))) -> Bounced | F15: =IF(ISNUMBER($E15),D15+14,"") | G15: =IF(ISNUMBER($E15),F15+14,"") | H15: =IF(ISNUMBER($E15),G15+14,"") | I15: =IF(ISNUMBER($E15),H15+14,"") | J15: =IF(NOT(ISNUMBER($E15)),"",IF($E15>=F15,"Done",F15-TODAY())) | K15: =IF(NOT(ISNUMBER($E15)),"",IF($E15>=G15,"Done",G15-TODAY())) | L15: =IF(NOT(ISNUMBER($E15)),"",IF($E15>=H15,"Done",H15-TODAY())) | M15: =IF(NOT(ISNUMBER($E15)),"",IF($E15>=I15,"Done",I15-TODAY()))
A16: Advent | B16: =IF(COUNTIF('PE names final'!A:A, A16)+COUNTIF('PE porfolio names final'!A:A,A16)=1, "Yes", "Error") -> Yes | C16: {=_xlfn.IFS(AND(COUNTIF('PE names final'!A:A,A16)>0,COUNTIF('PE porfolio names final'!A:A,A16)>0),"PE & Portfolio",COUNTIF('PE names final'!A:A,A16)>0,"PE",COUNTIF('PE porfolio names final'!A:A,A16)>0,"Portfolio",TRUE,"")} -> PE | D16: =_xlfn.LET(_xlpm.L,IFERROR(_xlfn.XLOOKUP(A16,'PE names final'!A:A,'PE names final'!C:C),_xlfn.XLOOKUP(A16,'PE porfolio names final'!A:A,'PE porfolio names final'!C:C,"")),IF(_xlpm.L=0,"",_xlpm.L)) -> 46035 | E16: =_xlfn.LET(_xlpm.d,IFERROR(_xlfn.XLOOKUP(A16,'PE names final'!A:A,'PE names final'!D:D),_xlfn.XLOOKUP(A16,'PE porfolio names final'!A:A,'PE porfolio names final'!D:D,"")),IF(_xlpm.d=0,"",IF(_xlpm.d<D16,"Error",_xlpm.d))) -> 46091 | F16: =IF(ISNUMBER($E16),D16+14,"") -> 46049 | G16: =IF(ISNUMBER($E16),F16+14,"") -> 46063 | H16: =IF(ISNUMBER($E16),G16+14,"") -> 46077 | I16: =IF(ISNUMBER($E16),H16+14,"") -> 46091 | J16: =IF(NOT(ISNUMBER($E16)),"",IF($E16>=F16,"Done",F16-TODAY())) -> Done | K16: =IF(NOT(ISNUMBER($E16)),"",IF($E16>=G16,"Done",G16-TODAY())) -> Done | L16: =IF(NOT(ISNUMBER($E16)),"",IF($E16>=H16,"Done",H16-TODAY())) -> Done | M16: =IF(NOT(ISNUMBER($E16)),"",IF($E16>=I16,"Done",I16-TODAY())) -> Done
A17: Kedaara | B17: =IF(COUNTIF('PE names final'!A:A, A17)+COUNTIF('PE porfolio names final'!A:A,A17)=1, "Yes", "Error") -> Yes | C17: {=_xlfn.IFS(AND(COUNTIF('PE names final'!A:A,A17)>0,COUNTIF('PE porfolio names final'!A:A,A17)>0),"PE & Portfolio",COUNTIF('PE names final'!A:A,A17)>0,"PE",COUNTIF('PE porfolio names final'!A:A,A17)>0,"Portfolio",TRUE,"")} -> PE | D17: =_xlfn.LET(_xlpm.L,IFERROR(_xlfn.XLOOKUP(A17,'PE names final'!A:A,'PE names final'!C:C),_xlfn.XLOOKUP(A17,'PE porfolio names final'!A:A,'PE porfolio names final'!C:C,"")),IF(_xlpm.L=0,"",_xlpm.L)) -> 46034 | E17: =_xlfn.LET(_xlpm.d,IFERROR(_xlfn.XLOOKUP(A17,'PE names final'!A:A,'PE names final'!D:D),_xlfn.XLOOKUP(A17,'PE porfolio names final'!A:A,'PE porfolio names final'!D:D,"")),IF(_xlpm.d=0,"",IF(_xlpm.d<D17,"Error",_xlpm.d))) -> Got response | F17: =IF(ISNUMBER($E17),D17+14,"") | G17: =IF(ISNUMBER($E17),F17+14,"") | H17: =IF(ISNUMBER($E17),G17+14,"") | I17: =IF(ISNUMBER($E17),H17+14,"") | J17: =IF(NOT(ISNUMBER($E17)),"",IF($E17>=F17,"Done",F17-TODAY())) | K17: =IF(NOT(ISNUMBER($E17)),"",IF($E17>=G17,"Done",G17-TODAY())) | L17: =IF(NOT(ISNUMBER($E17)),"",IF($E17>=H17,"Done",H17-TODAY())) | M17: =IF(NOT(ISNUMBER($E17)),"",IF($E17>=I17,"Done",I17-TODAY()))
A18: 8 Roads | B18: =IF(COUNTIF('PE names final'!A:A, A18)+COUNTIF('PE porfolio names final'!A:A,A18)=1, "Yes", "Error") -> Yes | C18: {=_xlfn.IFS(AND(COUNTIF('PE names final'!A:A,A18)>0,COUNTIF('PE porfolio names final'!A:A,A18)>0),"PE & Portfolio",COUNTIF('PE names final'!A:A,A18)>0,"PE",COUNTIF('PE porfolio names final'!A:A,A18)>0,"Portfolio",TRUE,"")} -> PE | D18: =_xlfn.LET(_xlpm.L,IFERROR(_xlfn.XLOOKUP(A18,'PE names final'!A:A,'PE names final'!C:C),_xlfn.XLOOKUP(A18,'PE porfolio names final'!A:A,'PE porfolio names final'!C:C,"")),IF(_xlpm.L=0,"",_xlpm.L)) -> 46055 | E18: =_xlfn.LET(_xlpm.d,IFERROR(_xlfn.XLOOKUP(A18,'PE names final'!A:A,'PE names final'!D:D),_xlfn.XLOOKUP(A18,'PE porfolio names final'!A:A,'PE porfolio names final'!D:D,"")),IF(_xlpm.d=0,"",IF(_xlpm.d<D18,"Error",_xlpm.d))) -> 46111 | F18: =IF(ISNUMBER($E18),D18+14,"") -> 46069 | G18: =IF(ISNUMBER($E18),F18+14,"") -> 46083 | H18: =IF(ISNUMBER($E18),G18+14,"") -> 46097 | I18: =IF(ISNUMBER($E18),H18+14,"") -> 46111 | J18: =IF(NOT(ISNUMBER($E18)),"",IF($E18>=F18,"Done",F18-TODAY())) -> Done | K18: =IF(NOT(ISNUMBER($E18)),"",IF($E18>=G18,"Done",G18-TODAY())) -> Done | L18: =IF(NOT(ISNUMBER($E18)),"",IF($E18>=H18,"Done",H18-TODAY())) -> Done | M18: =IF(NOT(ISNUMBER($E18)),"",IF($E18>=I18,"Done",I18-TODAY())) -> Done
A19: Convergent Finance | B19: =IF(COUNTIF('PE names final'!A:A, A19)+COUNTIF('PE porfolio names final'!A:A,A19)=1, "Yes", "Error") -> Yes | C19: {=_xlfn.IFS(AND(COUNTIF('PE names final'!A:A,A19)>0,COUNTIF('PE porfolio names final'!A:A,A19)>0),"PE & Portfolio",COUNTIF('PE names final'!A:A,A19)>0,"PE",COUNTIF('PE porfolio names final'!A:A,A19)>0,"Portfolio",TRUE,"")} -> PE | D19: =_xlfn.LET(_xlpm.L,IFERROR(_xlfn.XLOOKUP(A19,'PE names final'!A:A,'PE names final'!C:C),_xlfn.XLOOKUP(A19,'PE porfolio names final'!A:A,'PE porfolio names final'!C:C,"")),IF(_xlpm.L=0,"",_xlpm.L)) -> 46034 | E19: =_xlfn.LET(_xlpm.d,IFERROR(_xlfn.XLOOKUP(A19,'PE names final'!A:A,'PE names final'!D:D),_xlfn.XLOOKUP(A19,'PE porfolio names final'!A:A,'PE porfolio names final'!D:D,"")),IF(_xlpm.d=0,"",IF(_xlpm.d<D19,"Error",_xlpm.d))) -> 46091 | F19: =IF(ISNUMBER($E19),D19+14,"") -> 46048 | G19: =IF(ISNUMBER($E19),F19+14,"") -> 46062 | H19: =IF(ISNUMBER($E19),G19+14,"") -> 46076 | I19: =IF(ISNUMBER($E19),H19+14,"") -> 46090 | J19: =IF(NOT(ISNUMBER($E19)),"",IF($E19>=F19,"Done",F19-TODAY())) -> Done | K19: =IF(NOT(ISNUMBER($E19)),"",IF($E19>=G19,"Done",G19-TODAY())) -> Done | L19: =IF(NOT(ISNUMBER($E19)),"",IF($E19>=H19,"Done",H19-TODAY())) -> Done | M19: =IF(NOT(ISNUMBER($E19)),"",IF($E19>=I19,"Done",I19-TODAY())) -> Done
... A136: In2IT Technologies | B136: =IF(COUNTIF('PE names final'!A:A, A136)+COUNTIF('PE porfolio names final'!A:A,A136)=1, "Yes", "Error") -> Yes | C136: {=_xlfn.IFS(AND(COUNTIF('PE names final'!A:A,A136)>0,COUNTIF('PE porfolio names final'!A:A,A136)>0),"PE & Portfolio",COUNTIF('PE names final'!A:A,A136)>0,"PE",COUNTIF('PE porfolio names final'!A:A,A136)>0,"Portfolio",TRUE,"")} -> Portfolio | D136: =_xlfn.LET(_xlpm.L,IFERROR(_xlfn.XLOOKUP(A136,'PE names final'!A:A,'PE names final'!C:C),_xlfn.XLOOKUP(A136,'PE porfolio names final'!A:A,'PE porfolio names final'!C:C,"")),IF(_xlpm.L=0,"",_xlpm.L)) -> 46163 | E136: =_xlfn.LET(_xlpm.d,IFERROR(_xlfn.XLOOKUP(A136,'PE names final'!A:A,'PE names final'!D:D),_xlfn.XLOOKUP(A136,'PE porfolio names final'!A:A,'PE porfolio names final'!D:D,"")),IF(_xlpm.d=0,"",IF(_xlpm.d<D136,"Error",_xlpm.d))) -> Got response | F136: =IF(ISNUMBER($E136),D136+14,"") | G136: =IF(ISNUMBER($E136),F136+14,"") | H136: =IF(ISNUMBER($E136),G136+14,"") | I136: =IF(ISNUMBER($E136),H136+14,"") | J136: =IF(NOT(ISNUMBER($E136)),"",IF($E136>=F136,"Done",F136-TODAY())) | K136: =IF(NOT(ISNUMBER($E136)),"",IF($E136>=G136,"Done",G136-TODAY())) | L136: =IF(NOT(ISNUMBER($E136)),"",IF($E136>=H136,"Done",H136-TODAY())) | M136: =IF(NOT(ISNUMBER($E136)),"",IF($E136>=I136,"Done",I136-TODAY()))

Sheet Additional >>>

Sheet Remaining PE companies
B1: Remaining private equity buyers - 22by7
A4: S.No. | B4: Company name | C4: HQ | D4: Website | E4: Bucket | F4: Notes
A5: 1 | B5: 8 Roads | C5: Bermuda | D5: https://eightroads.com/en/ | E5: Foreign PE with potfolio companies not having Indian offices
A6: 2 | B6: Advent | C6: United States | D6: https://www.adventinternational.com/ | E6: Foreign PE with potfolio companies not having Indian offices
A7: 3 | B7: Affirma Capital | C7: Singapore | D7: https://affirmacapital.com/ | E7: Foreign PE with potfolio companies not having Indian offices | F7: Relevant investments like Redington
A8: 4 | B8: Arlington Capital Partners | C8: USA | D8: https://arlingtoncap.com/ | E8: Foreign PE with potfolio companies not having Indian offices
A9: 5 | B9: Ascent Capital | C9: India | D9: https://ascentcapital.in/ | E9: Indian PEs with unrelated potfolio companies | F9: No direct investments but notable ones like Acko and Big Basket
A10: 6 | B10: Avataar Ventures | C10: India | D10: https://www.avataar.vc/ | E10: Indian PEs with unrelated potfolio companies | F10: No directly relevant investments; Safe (cybersecurity platform) scaled internationally
A11: 7 | B11: BGF | C11: UK | D11: https://www.bgf.co.uk/ | E11: Foreign PE with potfolio companies not having Indian offices | F11: UK based but highly relevant investments
A12: 8 | B12: Blue Alliance | C12: USA | D12: https://www.bluealliance.com/ | E12: Foreign PE with potfolio companies not having Indian offices
A13: 9 | B13: ChrysCapital | C13: Mauritius | D13: https://chryscapital.com/ | E13: Foreign PE with potfolio companies not having Indian offices
A14: 10 | B14: Convergent Finance | C14: India | D14: https://convergentfinance.com/ | E14: Indian PEs with unrelated potfolio companies | F14: No direct investments but notable ones like Onward Technologies in software and Thomas Cook (India)
A15: 11 | B15: Creador | C15: Malysia | D15: https://creador.com/ | E15: Foreign PE with potfolio companies not having Indian offices
A16: 28 | B16: Evergreen Services Group | C16: USA | D16: https://www.evergreensg.com/ | E16: Foreign PE with potfolio companies not having Indian offices
A17: 12 | B17: Gaja Capital | C17: India | D17: https://gajacapital.com/ | E17: Indian PEs with unrelated potfolio companies | F17: No direct investments but notable ones like Fractal Analytics in software and Avendus
A18: 13 | B18: Great Hill Partners | C18: USA | D18: https://www.greathillpartners.com/ | E18: Foreign PE with potfolio companies not having Indian offices | F18: Numerous prior relevant investments
A19: 14 | B19: Halyard Capital | C19: USA | D19: https://www.halyard.com/ | E19: Foreign PE with potfolio companies not having Indian offices
A20: 15 | B20: Investcorp | C20: Bahrain | D20: https://www.investcorp.com/ | E20: Indian PEs with unrelated potfolio companies | F20: Mid-market investments is India as well as Europe and the USA
A21: 16 | B21: Kedaara | C21: India | D21: https://kedaara.com/ | E21: Indian PEs with unrelated potfolio companies | F21: No directly relevant investments; Impetus and Neurealm (cybersecurity platform) - scaled internationally
A22: 17 | B22: Navis Capital Partners | C22: Malysia | D22: https://www.naviscapital.com/ | E22: Foreign PE with potfolio companies not having Indian offices
A23: 18 | B23: Petros Partners | C23: USA | D23: https://www.petrospartners.com/ | E23: Foreign PE with potfolio companies not having Indian offices
A24: 19 | B24: Premji Invest | C24: India | D24: https://in.premjiinvest.com/ | E24: Indian PEs with unrelated potfolio companies | F24: No direct investments but notable investments in software with potential to scale abroad
A25: 20 | B25: Prosperity7 Ventures | C25: Saudi Arabia | D25: https://www.prosperity7vc.com/ | E25: Foreign PE with potfolio companies not having Indian offices
A26: 21 | B26: Runtide Capital | C26: USA | D26: https://www.runtidecapital.com/ | E26: Foreign PE with potfolio companies not having Indian offices
A27: 22 | B27: Samara Capital | C27: India | D27: https://samaracapital.com/ | E27: Indian PEs with unrelated potfolio companies | F27: No direct investments but notable ones like First Meridian and SMS
A28: 23 | B28: Stakeboat Capital | C28: India | D28: https://stakeboat.com/ | E28: Indian PEs with unrelated potfolio companies | F28: No direct investments but notable ones like Ozonotel (software) - scaled internationally
A29: 24 | B29: Steadview Capital | C29: UK | D29: https://www.steadview.com/ | E29: Foreign PE with potfolio companies not having Indian offices
A30: 25 | B30: Sunstone Partners | C30: USA | D30: https://sunstonepartners.com/ | E30: Foreign PE with potfolio companies not having Indian offices
A31: 26 | B31: Transom Capital | C31: USA | D31: https://transomcap.com/ | E31: Foreign PE with potfolio companies not having Indian offices
A32: 27 | B32: Westbridge Capital | C32: India | D32: https://westbridgecap.com/ | E32: Indian PEs with unrelated potfolio companies | F32: No directly relevant investments; Invests in leading businesses and Indian brands (Mindtree, Cognizant, etc.) - scaling internationally

Sheet PE summary analysis
A3: Holding company | B3: Repetitions | E3: Holding company | F3: Repetitions | I3: Holding company | J3: Expand Indian presence | K3: Expand Asian presence | L3: Offshore/onshore expansion | M3: Total
A4: Abry Partners | B4: =COUNTIF('PE porfolio names final'!$R:$R,'PE summary analysis'!$A4) -> 2 | E4: MC Partners | F4: =_xlfn.XLOOKUP(E4,A:A,B:B) -> 5 | I4: MC Partners | J4: =COUNTIFS('PE porfolio names final'!$R:$R,$I4,'PE porfolio names final'!$T:$T,J$3) -> 1 | K4: =COUNTIFS('PE porfolio names final'!$R:$R,$I4,'PE porfolio names final'!$T:$T,K$3) -> 1 | L4: =COUNTIFS('PE porfolio names final'!$R:$R,$I4,'PE porfolio names final'!$T:$T,L$3) -> 3 | M4: =SUM(J4:L4) -> 5
A5: Agellus Capital | B5: =COUNTIF('PE porfolio names final'!$R:$R,'PE summary analysis'!$A5) -> 1 | E5: Abry Partners | F5: =_xlfn.XLOOKUP(E5,A:A,B:B) -> 2 | I5: Abry Partners | J5: =COUNTIFS('PE porfolio names final'!$R:$R,$I5,'PE porfolio names final'!$T:$T,J$3) -> 1 | K5: =COUNTIFS('PE porfolio names final'!$R:$R,$I5,'PE porfolio names final'!$T:$T,K$3) -> 0 | L5: =COUNTIFS('PE porfolio names final'!$R:$R,$I5,'PE porfolio names final'!$T:$T,L$3) -> 1 | M5: =SUM(J5:L5) -> 2
A6: Atlantic Street Capital | B6: =COUNTIF('PE porfolio names final'!$R:$R,'PE summary analysis'!$A6) -> 1 | E6: Bregal Sagemount | F6: =_xlfn.XLOOKUP(E6,A:A,B:B) -> 2 | I6: Bregal Sagemount | J6: =COUNTIFS('PE porfolio names final'!$R:$R,$I6,'PE porfolio names final'!$T:$T,J$3) -> 0 | K6: =COUNTIFS('PE porfolio names final'!$R:$R,$I6,'PE porfolio names final'!$T:$T,K$3) -> 0 | L6: =COUNTIFS('PE porfolio names final'!$R:$R,$I6,'PE porfolio names final'!$T:$T,L$3) -> 2 | M6: =SUM(J6:L6) -> 2
A7: Bregal Sagemount | B7: =COUNTIF('PE porfolio names final'!$R:$R,'PE summary analysis'!$A7) -> 2 | E7: Frontenac | F7: =_xlfn.XLOOKUP(E7,A:A,B:B) -> 2 | I7: Frontenac | J7: =COUNTIFS('PE porfolio names final'!$R:$R,$I7,'PE porfolio names final'!$T:$T,J$3) -> 0 | K7: =COUNTIFS('PE porfolio names final'!$R:$R,$I7,'PE porfolio names final'!$T:$T,K$3) -> 0 | L7: =COUNTIFS('PE porfolio names final'!$R:$R,$I7,'PE porfolio names final'!$T:$T,L$3) -> 2 | M7: =SUM(J7:L7) -> 2
A8: Court Square | B8: =COUNTIF('PE porfolio names final'!$R:$R,'PE summary analysis'!$A8) -> 1 | E8: Fulcrum IT partners | F8: =_xlfn.XLOOKUP(E8,A:A,B:B) -> 2 | I8: Fulcrum IT partners | J8: =COUNTIFS('PE porfolio names final'!$R:$R,$I8,'PE porfolio names final'!$T:$T,J$3) -> 0 | K8: =COUNTIFS('PE porfolio names final'!$R:$R,$I8,'PE porfolio names final'!$T:$T,K$3) -> 0 | L8: =COUNTIFS('PE porfolio names final'!$R:$R,$I8,'PE porfolio names final'!$T:$T,L$3) -> 2 | M8: =SUM(J8:L8) -> 2
A9: FFL Group | B9: =COUNTIF('PE porfolio names final'!$R:$R,'PE summary analysis'!$A9) -> 1 | E9: HIG Capital | F9: =_xlfn.XLOOKUP(E9,A:A,B:B) -> 2 | I9: HIG Capital | J9: =COUNTIFS('PE porfolio names final'!$R:$R,$I9,'PE porfolio names final'!$T:$T,J$3) -> 0 | K9: =COUNTIFS('PE porfolio names final'!$R:$R,$I9,'PE porfolio names final'!$T:$T,K$3) -> 0 | L9: =COUNTIFS('PE porfolio names final'!$R:$R,$I9,'PE porfolio names final'!$T:$T,L$3) -> 2 | M9: =SUM(J9:L9) -> 2
A10: Frontenac | B10: =COUNTIF('PE porfolio names final'!$R:$R,'PE summary analysis'!$A10) -> 2 | E10: Oval Partners | F10: =_xlfn.XLOOKUP(E10,A:A,B:B) -> 1 | I10: Oval Partners | J10: =COUNTIFS('PE porfolio names final'!$R:$R,$I10,'PE porfolio names final'!$T:$T,J$3) -> 0 | K10: =COUNTIFS('PE porfolio names final'!$R:$R,$I10,'PE porfolio names final'!$T:$T,K$3) -> 0 | L10: =COUNTIFS('PE porfolio names final'!$R:$R,$I10,'PE porfolio names final'!$T:$T,L$3) -> 1 | M10: =SUM(J10:L10) -> 1
A11: Fulcrum IT partners | B11: =COUNTIF('PE porfolio names final'!$R:$R,'PE summary analysis'!$A11) -> 2 | E11: Recognize | F11: =_xlfn.XLOOKUP(E11,A:A,B:B) -> 2 | I11: Recognize | J11: =COUNTIFS('PE porfolio names final'!$R:$R,$I11,'PE porfolio names final'!$T:$T,J$3) -> 1 | K11: =COUNTIFS('PE porfolio names final'!$R:$R,$I11,'PE porfolio names final'!$T:$T,K$3) -> 0 | L11: =COUNTIFS('PE porfolio names final'!$R:$R,$I11,'PE porfolio names final'!$T:$T,L$3) -> 1 | M11: =SUM(J11:L11) -> 2
A12: HCAP Partners | B12: =COUNTIF('PE porfolio names final'!$R:$R,'PE summary analysis'!$A12) -> 1 | E12: Agellus Capital | F12: =_xlfn.XLOOKUP(E12,A:A,B:B) -> 1 | I12: Agellus Capital | J12: =COUNTIFS('PE porfolio names final'!$R:$R,$I12,'PE porfolio names final'!$T:$T,J$3) -> 0 | K12: =COUNTIFS('PE porfolio names final'!$R:$R,$I12,'PE porfolio names final'!$T:$T,K$3) -> 0 | L12: =COUNTIFS('PE porfolio names final'!$R:$R,$I12,'PE porfolio names final'!$T:$T,L$3) -> 1 | M12: =SUM(J12:L12) -> 1
A13: HIG Capital | B13: =COUNTIF('PE porfolio names final'!$R:$R,'PE summary analysis'!$A13) -> 2 | E13: Atlantic Street Capital | F13: =_xlfn.XLOOKUP(E13,A:A,B:B) -> 1 | I13: Atlantic Street Capital | J13: =COUNTIFS('PE porfolio names final'!$R:$R,$I13,'PE porfolio names final'!$T:$T,J$3) -> 0 | K13: =COUNTIFS('PE porfolio names final'!$R:$R,$I13,'PE porfolio names final'!$T:$T,K$3) -> 0 | L13: =COUNTIFS('PE porfolio names final'!$R:$R,$I13,'PE porfolio names final'!$T:$T,L$3) -> 1 | M13: =SUM(J13:L13) -> 1
A14: Insight Partners | B14: =COUNTIF('PE porfolio names final'!$R:$R,'PE summary analysis'!$A14) -> 1 | E14: Court Square | F14: =_xlfn.XLOOKUP(E14,A:A,B:B) -> 1 | I14: Court Square | J14: =COUNTIFS('PE porfolio names final'!$R:$R,$I14,'PE porfolio names final'!$T:$T,J$3) -> 0 | K14: =COUNTIFS('PE porfolio names final'!$R:$R,$I14,'PE porfolio names final'!$T:$T,K$3) -> 0 | L14: =COUNTIFS('PE porfolio names final'!$R:$R,$I14,'PE porfolio names final'!$T:$T,L$3) -> 1 | M14: =SUM(J14:L14) -> 1
A15: Intel Capital | B15: =COUNTIF('PE porfolio names final'!$R:$R,'PE summary analysis'!$A15) -> 1 | E15: FFL Group | F15: =_xlfn.XLOOKUP(E15,A:A,B:B) -> 1 | I15: FFL Group | J15: =COUNTIFS('PE porfolio names final'!$R:$R,$I15,'PE porfolio names final'!$T:$T,J$3) -> 0 | K15: =COUNTIFS('PE porfolio names final'!$R:$R,$I15,'PE porfolio names final'!$T:$T,K$3) -> 0 | L15: =COUNTIFS('PE porfolio names final'!$R:$R,$I15,'PE porfolio names final'!$T:$T,L$3) -> 1 | M15: =SUM(J15:L15) -> 1
... A37: VSS Capital Partners | B37: =COUNTIF('PE porfolio names final'!$R:$R,'PE summary analysis'!$A37) -> 1 | E37: VSS Capital Partners | F37: =_xlfn.XLOOKUP(E37,A:A,B:B) -> 1 | I37: VSS Capital Partners | J37: =COUNTIFS('PE porfolio names final'!$R:$R,$I37,'PE porfolio names final'!$T:$T,J$3) -> 1 | K37: =COUNTIFS('PE porfolio names final'!$R:$R,$I37,'PE porfolio names final'!$T:$T,K$3) -> 0 | L37: =COUNTIFS('PE porfolio names final'!$R:$R,$I37,'PE porfolio names final'!$T:$T,L$3) -> 0 | M37: =SUM(J37:L37) -> 1
I38: Total | J38: =SUM(J4:J37) -> 9 | K38: =SUM(K4:K37) -> 1 | L38: =SUM(L4:L37) -> 34 | M38: =SUM(M4:M37) -> 44

Sheet PE names
A1: Private equity buyers - 22by7
B3: =SUBTOTAL(3,B4:B1048576) -> 63
A4: S.No. | B4: Company name | C4: HQ | D4: Cheque size | E4: Porfolio companies | F4: Deal rationale | G4: Website | H4: Status | I4: Next Follow-up Date | J4: Contact Name | K4: Designation | L4: Email Id | M4: Linkedin
A5: 1 | B5: Trunorth | C5: India | D5: N/A / mid market | E5: Accion labs, iLink Digital | F5: Relevent prior investments seem to be large in size in comparison the 22by7; prior investments have taken a stance in the US | G5: https://www.truenorth.co.in/ | J5: Mahinder Singh Juneja | K5: Partner | L5: maninder@truenorth.co.in | M5: https://www.linkedin.com/in/maninder-singh-juneja-35a01a13/
A6: =A5+1 -> 2 | B6: Advent | C6: USA | D6: $50m - $2b (Advent Tech II Fund) | E6: Tredence | F6: Relevant prior invrstments, however ticket sizes may be seen as too large | G6: https://www.adventinternational.com/ | J6: Mohammed Anjarwala | K6: Partner | L6: manjarwala@adventinternational.com | M6: https://www.linkedin.com/in/anjarwala/
A7: =A6+1 -> 3 | B7: Kedaara | C7: India | D7: N/A | E7: Impetus, Neurealm | F7: Relevent prior investments seem to be large in size in comparison the 22by7; prior investments have taken a stance in the US | G7: https://kedaara.com/ | J7: Manish Kejriwal | K7: Founder/Managing Partner | L7: manish.kejriwal@kedaara.com | M7: https://www.linkedin.com/in/manish-kejriwal-1a7336/
A8: =A7+1 -> 4 | B8: 8 Roads | C8: Bermuda | D8: N/A | E8: Safe, Whatfix | F8: From precedent transactions | G8: https://eightroads.com/en/ | J8: Gordon Zhang | K8: Partner | L8: gordon.zhang@eightroads.com | M8: https://www.linkedin.com/in/gordon-zhang-9490b3273/
A9: =A8+1 -> 5 | B9: Convergent Finance | C9: India | D9: N/A | E9: Onward Technologies | F9: HIGHLY RELEVANT; From precedent transactions | G9: https://convergentfinance.com/ | J9: Harsha Raghavan | K9: Managing Partner | L9: harsha@convergentfinance.com | M9: https://www.linkedin.com/in/harsha-raghavan-1218a11b5/
A10: =A9+1 -> 6 | B10: Premji Invest | C10: India | D10: N/A | E10: Increff, Lambda Test | F10: Close investments in businesses that utlise cloud services | G10: https://in.premjiinvest.com/ | J10: Kaveesh Chawla | K10: Partner | L10: kaveesh.chawla@premjiinvest.com | M10: https://www.linkedin.com/in/kaveeshchawla/
